Workbook

Sheet Depletion Report
A1: Total Depletions from all Cleansing Smoothies Distributors for the Last 90 days (aggregated)
B3: SKU | C3: Total Units | K3: SFO | L3: LAX | M3: BOS | N3: JFK
B4: CSA | C4: =SUM(B13:B102) -> 69541 | I4: Sum | J4: CSA | K4: ='CSA Report'!C3 -> 4507 | L4: ='CSA Report'!D3 -> 8092 | M4: ='CSA Report'!E3 -> 23130 | N4: ='CSA Report'!F3 -> 14206
B5: CSB | C5: =SUM(C13:C102) -> 11786 | J5: CSE | K5: ='CSE Report'!C3 -> 775 | L5: ='CSE Report'!D3 -> 1686 | M5: ='CSE Report'!E3 -> 4525 | N5: ='CSE Report'!F3 -> 3625
B6: CSC | C6: =SUM(D13:D102) -> 62920
B7: CSD | C7: =SUM(E13:E102) -> 37483 | I7: Mean | J7: CSA | K7: ='CSA Report'!C4 -> 50.077778 | L7: ='CSA Report'!D4 -> 89.911111 | M7: ='CSA Report'!E4 -> 257 | N7: ='CSA Report'!F4 -> 157.84444
B8: CSE | C8: =SUM(F13:F102) -> 15266 | J8: CSE | K8: ='CSE Report'!C4 -> 8.6111111 | L8: ='CSE Report'!D4 -> 18.733333 | M8: ='CSE Report'!E4 -> 50.277778 | N8: ='CSE Report'!F4 -> 40.277778
A10: Total Depletions from all Cleansing Smoothie Distributors for the Last 90 days (by day) | I10: SD | J10: CSA | K10: ='CSA Report'!C5 -> 34.607341 | L10: ='CSA Report'!D5 -> 65.240376 | M10: ='CSA Report'!E5 -> 142.77853 | N10: ='CSA Report'!F5 -> 97.091167
J11: CSE | K11: ='CSE Report'!C5 -> 7.8678616 | L11: ='CSE Report'!D5 -> 14.664641 | M11: ='CSE Report'!E5 -> 37.607681 | N11: ='CSE Report'!F5 -> 38.76406
A12: Day | B12: CSA | C12: CSB | D12: CSC | E12: CSD | F12: CSE
A13: 1 | B13: 653 | C13: 146 | D13: 687 | E13: 575 | F13: 343 | J13: R | K13: 5 | L13: 5 | M13: 1 | N13: 2
A14: 2 | B14: 989 | C14: 101 | D14: 257 | E14: 124 | F14: 84 | J14: L | K14: 5 | L14: 5 | M14: 1 | N14: 3
A15: 3 | B15: 906 | C15: 192 | D15: 608 | E15: 305 | F15: 22
A16: 4 | B16: 534 | C16: 35 | D16: 876 | E16: 189 | F16: 69 | J16: CSL | K16: 0.98 | L16: 0.98 | M16: 0.98 | N16: 0.98
A17: 5 | B17: 591 | C17: 53 | D17: 509 | E17: 253 | F17: 223 | J17: Z | K17: =_xlfn.NORM.S.INV(K16) -> 2.0537489 | L17: =_xlfn.NORM.S.INV(L16) -> 2.0537489 | M17: =_xlfn.NORM.S.INV(M16) -> 2.0537489 | N17: =_xlfn.NORM.S.INV(N16) -> 2.0537489
A18: 6 | B18: 654 | C18: 31 | D18: 905 | E18: 221 | F18: 64
A19: 7 | B19: 696 | C19: 134 | D19: 892 | E19: 458 | F19: 246 | I19: SS | J19: CSA | K19: =K$17*K10*POWER(K13+K14,0.5) -> 224.75822 | L19: =L$17*L10*POWER(L13+L14,0.5) -> 423.70521 | M19: =M$17*M10*POWER(M13+M14,0.5) -> 414.6916 | N19: =N$17*N10*POWER(N13+N14,0.5) -> 445.87392
A20: 8 | B20: 544 | C20: 224 | D20: 496 | E20: 272 | F20: 230 | J20: CSE | K20: =K$17*K11*POWER(K13+K14,0.5) -> 51.098018 | L20: =L$17*L11*POWER(L13+L14,0.5) -> 95.239865 | M20: =M$17*M11*POWER(M13+M14,0.5) -> 109.22924 | N20: =N$17*N11*POWER(N13+N14,0.5) -> 178.01705
A21: 9 | B21: 689 | C21: 126 | D21: 634 | E21: 769 | F21: 179
A22: 10 | B22: 610 | C22: 83 | D22: 526 | E22: 522 | F22: 62 | I22: CS | J22: CSA | K22: =(K13+K14)*K7 -> 500.77778 | L22: =(L13+L14)*L7 -> 899.11111 | M22: =(M13+M14)*M7 -> 514 | N22: =(N13+N14)*N7 -> 789.22222
A23: 11 | B23: 511 | C23: 85 | D23: 756 | E23: 592 | F23: 158 | J23: CSE | K23: =(K13+K14)*K8 -> 86.111111 | L23: =(L13+L14)*L8 -> 187.33333 | M23: =(M13+M14)*M8 -> 100.55556 | N23: =(N13+N14)*N8 -> 201.38889
A24: 12 | B24: 983 | C24: 165 | D24: 511 | E24: 425 | F24: 180
A25: 13 | B25: 666 | C25: 47 | D25: 686 | E25: 438 | F25: 305 | I25: AIOH | J25: CSA | K25: =K19+(K$13*K7*0.5) -> 349.95266 | L25: =L19+(L$13*L7*0.5) -> 648.48298 | M25: =M19+(M$13*M7*0.5) -> 543.1916 | N25: =N19+(N$13*N7*0.5) -> 603.71836
A26: 14 | B26: 372 | C26: 185 | D26: 935 | E26: 341 | F26: 134 | J26: CSE | K26: =K20+(K$13*K8*0.5) -> 72.625796 | L26: =L20+(L$13*L8*0.5) -> 142.0732 | M26: =M20+(M$13*M8*0.5) -> 134.36813 | N26: =N20+(N$13*N8*0.5) -> 218.29483
A27: 15 | B27: 844 | C27: 107 | D27: 660 | E27: 596 | F27: 410
A28: 16 | B28: 908 | C28: 137 | D28: 923 | E28: 587 | F28: 225 | I28: Actual | J28: CSA | K28: ='Inventory Report'!C7 -> 150 | L28: ='Inventory Report'!C6 -> 270 | M28: ='Inventory Report'!C4 -> 771 | N28: ='Inventory Report'!C5 -> 473
A29: 17 | B29: 711 | C29: 148 | D29: 572 | E29: 261 | F29: 214 | I29: IOH | J29: CSE | K29: ='Inventory Report'!D7 -> 26 | L29: ='Inventory Report'!D6 -> 56 | M29: ='Inventory Report'!D4 -> 151 | N29: ='Inventory Report'!D5 -> 121
A30: 18 | B30: 951 | C30: -30 | D30: 652 | E30: 409 | F30: 136
A31: 19 | B31: 1152 | C31: 97 | D31: 841 | E31: 475 | F31: 254 | I31: EPL | J31: CSA | K31: =K$14*K7 -> 250.38889 | L31: =L$14*L7 -> 449.55556 | M31: =M$14*M7 -> 257 | N31: =N$14*N7 -> 473.53333
A32: 20 | B32: 1120 | C32: 100 | D32: 547 | E32: 215 | F32: 62 | J32: CSE | K32: =K$14*K8 -> 43.055556 | L32: =L$14*L8 -> 93.666667 | M32: =M$14*M8 -> 50.277778 | N32: =N$14*N8 -> 120.83333
A33: 21 | B33: 436 | C33: 98 | D33: 505 | E33: 284 | F33: 108
A34: 22 | B34: 729 | C34: 81 | D34: 783 | E34: 617 | F34: 117
A35: 23 | B35: 620 | C35: 183 | D35: 553 | E35: 223 | F35: 128
A36: 24 | B36: 848 | C36: 68 | D36: 789 | E36: 347 | F36: 238
A37: 25 | B37: 537 | C37: 49 | D37: 794 | E37: 433 | F37: 235
A38: 26 | B38: 564 | C38: 250 | D38: 706 | E38: 45 | F38: 113
A39: 27 | B39: 720 | C39: 168 | D39: 1016 | E39: 628 | F39: 111
A40: 28 | B40: 920 | C40: 255 | D40: 618 | E40: 321 | F40: 37
A41: 29 | B41: 776 | C41: 107 | D41: 952 | E41: 620 | F41: 356
A42: 30 | B42: 811 | C42: 143 | D42: 589 | E42: 334 | F42: 23
...

Sheet Inventory Report
A1: Current Inventory Report for SKUs CSA and CSE at Distributors BOS, JFK, LAX, and SFO
B3: Distributor | C3: Daily Actual Average Inventory On Hand for CSA | D3: Daily Actual Average Inventory On Hand for CSE | E3: Review Period | F3: Leadtime
B4: BOS | C4: 771 | D4: 151 | E4: 1 | F4: 1
B5: JFK | C5: 473 | D5: 121 | E5: 2 | F5: 3
B6: LAX | C6: 270 | D6: 56 | E6: 5 | F6: 5
B7: SFO | C7: 150 | D7: 26 | E7: 5 | F7: 5

Sheet CSA Report
A1: Last 90 Days of Depletions of SKU CSA at Four Distributors
B3: sum | C3: =SUM(C9:C98) -> 4507 | D3: =SUM(D9:D98) -> 8092 | E3: =SUM(E9:E98) -> 23130 | F3: =SUM(F9:F98) -> 14206
B4: mean | C4: =AVERAGE(C9:C98) -> 50.077778 | D4: =AVERAGE(D9:D98) -> 89.911111 | E4: =AVERAGE(E9:E98) -> 257 | F4: =AVERAGE(F9:F98) -> 157.84444
B5: sd | C5: =_xlfn.STDEV.S(C9:C98) -> 34.607341 | D5: =_xlfn.STDEV.S(D9:D98) -> 65.240376 | E5: =_xlfn.STDEV.S(E9:E98) -> 142.77853 | F5: =_xlfn.STDEV.S(F9:F98) -> 97.091167
B8: Day | C8: SFO | D8: LAX | E8: BOS | F8: JFK | G8: sum
B9: 1 | C9: 26 | D9: 42 | E9: 322 | F9: 12 | G9: =SUM(C9:F9) -> 402
B10: 2 | C10: 18 | D10: 92 | E10: 414 | F10: 192 | G10: =SUM(C10:F10) -> 716
B11: 3 | C11: 83 | D11: 55 | E11: 506 | F11: 94 | G11: =SUM(C11:F11) -> 738
B12: 4 | C12: 27 | D12: 240 | E12: 167 | F12: 41 | G12: =SUM(C12:F12) -> 475
B13: 5 | C13: 36 | D13: 55 | E13: 57 | F13: 253 | G13: =SUM(C13:F13) -> 401
B14: 6 | C14: 23 | D14: 70 | E14: 145 | F14: 220 | G14: =SUM(C14:F14) -> 458
B15: 7 | C15: 23 | D15: 57 | E15: 288 | F15: 119 | G15: =SUM(C15:F15) -> 487
B16: 8 | C16: 7 | D16: 5 | E16: 368 | F16: 64 | G16: =SUM(C16:F16) -> 444
B17: 9 | C17: 51 | D17: 44 | E17: 263 | F17: 138 | G17: =SUM(C17:F17) -> 496
B18: 10 | C18: 55 | D18: 1 | E18: 82 | F18: 176 | G18: =SUM(C18:F18) -> 314
B19: 11 | C19: 19 | D19: 56 | E19: 146 | F19: 130 | G19: =SUM(C19:F19) -> 351
B20: 12 | C20: 98 | D20: 123 | E20: 449 | F20: 115 | G20: =SUM(C20:F20) -> 785
... B98: 90 | C98: 96 | D98: 31 | E98: 58 | F98: 611 | G98: =SUM(C98:F98) -> 796

Sheet CSE Report
A1: Last 90 Days of Depletions of SKU CSE at Four Distributors
B3: sum | C3: =SUM(C9:C98) -> 775 | D3: =SUM(D9:D98) -> 1686 | E3: =SUM(E9:E98) -> 4525 | F3: =SUM(F9:F98) -> 3625
B4: mean | C4: =AVERAGE(C9:C98) -> 8.6111111 | D4: =AVERAGE(D9:D98) -> 18.733333 | E4: =AVERAGE(E9:E98) -> 50.277778 | F4: =AVERAGE(F9:F98) -> 40.277778
B5: sd | C5: =_xlfn.STDEV.S(C9:C98) -> 7.8678616 | D5: =_xlfn.STDEV.S(D9:D98) -> 14.664641 | E5: =_xlfn.STDEV.S(E9:E98) -> 37.607681 | F5: =_xlfn.STDEV.S(F9:F98) -> 38.76406
B8: Day | C8: SFO | D8: LAX | E8: BOS | F8: JFK
B9: 1 | C9: 19 | D9: 3 | E9: 103 | F9: 52
B10: 2 | C10: 3 | D10: 7 | E10: 49 | F10: 10
B11: 3 | C11: 1 | D11: 2 | E11: 7 | F11: 2
B12: 4 | C12: 4 | D12: 11 | E12: 5 | F12: 26
B13: 5 | C13: 24 | D13: 14 | E13: 80 | F13: 8
B14: 6 | C14: 1 | D14: 5 | E14: 23 | F14: 9
B15: 7 | C15: 16 | D15: 16 | E15: 27 | F15: 68
B16: 8 | C16: 1 | D16: 7 | E16: 60 | F16: 120
B17: 9 | C17: 13 | D17: 52 | E17: 23 | F17: 35
B18: 10 | C18: 1 | D18: 10 | E18: 27 | F18: 18
B19: 11 | C19: 0 | D19: 15 | E19: 31 | F19: 46
B20: 12 | C20: 5 | D20: 17 | E20: 72 | F20: 41
... B98: 90 | C98: 16 | D98: 42 | E98: 195 | F98: 10
