Workbook

Sheet Depletion Report
A1: Total Depletions from all Cleansing Smoothies Distributors for the Last 90 days (aggregated)
B3: SKU | C3: Total Units
B4: CSA | C4: =SUM(B13:B102) -> 69541
B5: CSB | C5: =SUM(C13:C102) -> 11786
B6: CSC | C6: =SUM(D13:D102) -> 62920
B7: CSD | C7: =SUM(E13:E102) -> 37483
B8: CSE | C8: =SUM(F13:F102) -> 15266
A10: Total Depletions from all Cleansing Smoothie Distributors for the Last 90 days (by day)
A12: Day | B12: CSA | C12: CSB | D12: CSC | E12: CSD | F12: CSE
A13: 1 | B13: 653 | C13: 146 | D13: 687 | E13: 575 | F13: 343 | G13: =SUM(B13:F13) -> 2404
A14: 2 | B14: 989 | C14: 101 | D14: 257 | E14: 124 | F14: 84 | G14: =SUM(B14:F14) -> 1555
A15: 3 | B15: 906 | C15: 192 | D15: 608 | E15: 305 | F15: 22 | G15: =SUM(B15:F15) -> 2033
A16: 4 | B16: 534 | C16: 35 | D16: 876 | E16: 189 | F16: 69 | G16: =SUM(B16:F16) -> 1703
A17: 5 | B17: 591 | C17: 53 | D17: 509 | E17: 253 | F17: 223 | G17: =SUM(B17:F17) -> 1629
A18: 6 | B18: 654 | C18: 31 | D18: 905 | E18: 221 | F18: 64 | G18: =SUM(B18:F18) -> 1875
A19: 7 | B19: 696 | C19: 134 | D19: 892 | E19: 458 | F19: 246 | G19: =SUM(B19:F19) -> 2426
A20: 8 | B20: 544 | C20: 224 | D20: 496 | E20: 272 | F20: 230 | G20: =SUM(B20:F20) -> 1766
A21: 9 | B21: 689 | C21: 126 | D21: 634 | E21: 769 | F21: 179 | G21: =SUM(B21:F21) -> 2397
A22: 10 | B22: 610 | C22: 83 | D22: 526 | E22: 522 | F22: 62 | G22: =SUM(B22:F22) -> 1803
A23: 11 | B23: 511 | C23: 85 | D23: 756 | E23: 592 | F23: 158 | G23: =SUM(B23:F23) -> 2102
A24: 12 | B24: 983 | C24: 165 | D24: 511 | E24: 425 | F24: 180 | G24: =SUM(B24:F24) -> 2264
... A101: 89 | B101: 675 | C101: 135 | D101: 334 | E101: 519 | F101: 100 | G101: =SUM(B101:F101) -> 1763
A102: 90 | B102: 1023 | C102: 160 | D102: 530 | E102: 489 | F102: 371 | G102: =SUM(B102:F102) -> 2573 | I102: Column G is only interesting to supply chain people
I103: never show to sales people
A104: min | B104: =MIN(B13:B102) -> 304 | C104: =MIN(C13:C102) -> -30 | D104: =MIN(D13:D102) -> 257 | E104: =MIN(E13:E102) -> 34 | F104: =MIN(F13:F102) -> 22 | G104: =MIN(G13:G102) -> 1431
A105: max | B105: =MAX(B13:B102) -> 1415 | C105: =MAX(C13:C102) -> 271 | D105: =MAX(D13:D102) -> 1081 | E105: =MAX(E13:E102) -> 838 | F105: =MAX(F13:F102) -> 410 | G105: =MAX(G13:G102) -> 3080
A106: average | B106: =AVERAGE(B13:B102) -> 772.67778 | C106: =AVERAGE(C13:C102) -> 130.95556 | D106: =AVERAGE(D13:D102) -> 699.11111 | E106: =AVERAGE(E13:E102) -> 416.47778 | F106: =AVERAGE(F13:F102) -> 169.62222 | G106: =AVERAGE(G13:G102) -> 2188.8444
A107: st dev | B107: =STDEV(B13:B102) -> 208.53221 | C107: =STDEV(C13:C102) -> 58.865856 | D107: =STDEV(D13:D102) -> 167.77282 | E107: =STDEV(E13:E102) -> 181.03418 | F107: =STDEV(F13:F102) -> 90.939241 | G107: =STDEV(G13:G102) -> 342.19926
A108: cv | B108: =B107/B106 -> 0.2698825 | C108: =C107/C106 -> 0.44951019 | D108: =D107/D106 -> 0.23998019 | E108: =E107/E106 -> 0.4346791 | F108: =F107/F106 -> 0.53612811 | G108: =G107/G106 -> 0.15633786
A110: Weekly analysis (first 84 days)
A112: Week | B112: CSA | C112: CSB | D112: CSC | E112: CSD | F112: CSE
A113: W1 | B113: =SUM(B13:B19) -> 5023 | C113: =SUM(C13:C19) -> 692 | D113: =SUM(D13:D19) -> 4734 | E113: =SUM(E13:E19) -> 2125 | F113: =SUM(F13:F19) -> 1051
A114: W2 | B114: =SUM(B20:B26) -> 4375 | C114: =SUM(C20:C26) -> 915 | D114: =SUM(D20:D26) -> 4544 | E114: =SUM(E20:E26) -> 3359 | F114: =SUM(F20:F26) -> 1248
A115: W3 | B115: =SUM(B27:B33) -> 6122 | C115: =SUM(C27:C33) -> 657 | D115: =SUM(D27:D33) -> 4700 | E115: =SUM(E27:E33) -> 2827 | F115: =SUM(F27:F33) -> 1409
A116: W4 | B116: =SUM(B34:B40) -> 4938 | C116: =SUM(C34:C40) -> 1054 | D116: =SUM(D34:D40) -> 5259 | E116: =SUM(E34:E40) -> 2614 | F116: =SUM(F34:F40) -> 979
A117: W5 | B117: =SUM(B41:B47) -> 4899 | C117: =SUM(C41:C47) -> 972 | D117: =SUM(D41:D47) -> 5256 | E117: =SUM(E41:E47) -> 3278 | F117: =SUM(F41:F47) -> 1188
A118: W6 | B118: =SUM(B48:B54) -> 5128 | C118: =SUM(C48:C54) -> 892 | D118: =SUM(D48:D54) -> 4734 | E118: =SUM(E48:E54) -> 3377 | F118: =SUM(F48:F54) -> 842
A119: W7 | B119: =SUM(B55:B61) -> 6267 | C119: =SUM(C55:C61) -> 780 | D119: =SUM(D55:D61) -> 4017 | E119: =SUM(E55:E61) -> 2682 | F119: =SUM(F55:F61) -> 1246
A120: W8 | B120: =SUM(B62:B68) -> 5791 | C120: =SUM(C62:C68) -> 1121 | D120: =SUM(D62:D68) -> 4784 | E120: =SUM(E62:E68) -> 2619 | F120: =SUM(F62:F68) -> 1394
A121: W9 | B121: =SUM(B69:B75) -> 5439 | C121: =SUM(C69:C75) -> 808 | D121: =SUM(D69:D75) -> 5733 | E121: =SUM(E69:E75) -> 2428 | F121: =SUM(F69:F75) -> 1411
...

Sheet Inventory Report
A1: Current Inventory Report for SKUs CSA and CSE at Distributors BOS, JFK, LAX, and SFO
I2: CSA
B3: Distributor | C3: Average Daily Inventory for CSA | D3: Average Daily Inventory for CSE | E3: Review Period | F3: Leadtime | I3: Distributor | J3: Review Period | K3: Leadtime | L3: avg daily demand | M3: sigma demand | N3: svc level target | O3: scientific expected inventory on hand | P3: actual average inventory on hand | Q3: delta | R3: imputed z | S3: imputed service | T3: scientific forward days of supply | U3: actual forward days of supply
B4: BOS | C4: 771 | D4: 151 | E4: 1 | F4: 1 | I4: BOS | J4: 1 | K4: 1 | L4: ='CSA Report'!E97 -> 257 | M4: ='CSA Report'!E98 -> 142.77853 | N4: 0.95 | O4: =ROUND(J4*L4/2+NORMSINV(N4)*M4*SQRT(J4+K4),0) -> 461 | P4: =C4 -> 771 | Q4: =P4-O4 -> 310 | R4: =(P4-J4*L4/2)/(M4*SQRT(J4+K4)) -> 3.1819638 | S4: =NORMSDIST((P4-J4*L4/2)/(M4*SQRT(J4+K4))) -> 0.9992686 | T4: =O4/L4 -> 1.7937743 | U4: =P4/L4 -> 3
B5: JFK | C5: 473 | D5: 121 | E5: 2 | F5: 3 | I5: JFK | J5: 2 | K5: 3 | L5: ='CSA Report'!F97 -> 157.84444 | M5: ='CSA Report'!F98 -> 97.091167 | N5: 0.95 | O5: =ROUND(J5*L5/2+NORMSINV(N5)*M5*SQRT(J5+K5),0) -> 515 | P5: =C5 -> 473 | Q5: =P5-O5 -> -42 | R5: =(P5-J5*L5/2)/(M5*SQRT(J5+K5)) -> 1.4516444 | S5: =NORMSDIST((P5-J5*L5/2)/(M5*SQRT(J5+K5))) -> 0.92669975 | T5: =O5/L5 -> 3.2627059 | U5: =P5/L5 -> 2.9966211
B6: LAX | C6: 270 | D6: 56 | E6: 5 | F6: 5 | I6: LAX | J6: 5 | K6: 5 | L6: ='CSA Report'!D97 -> 89.911111 | M6: ='CSA Report'!D98 -> 65.240376 | N6: 0.95 | O6: =ROUND(J6*L6/2+NORMSINV(N6)*M6*SQRT(J6+K6),0) -> 564 | P6: =C6 -> 270 | Q6: =P6-O6 -> -294 | R6: =(P6-J6*L6/2)/(M6*SQRT(J6+K6)) -> 0.21919742 | S6: =NORMSDIST((P6-J6*L6/2)/(M6*SQRT(J6+K6))) -> 0.58675187 | T6: =O6/L6 -> 6.2728621 | U6: =P6/L6 -> 3.0029659
B7: SFO | C7: 150 | D7: 26 | E7: 5 | F7: 5 | I7: SFO | J7: 5 | K7: 5 | L7: ='CSA Report'!C97 -> 50.077778 | M7: ='CSA Report'!C98 -> 34.607341 | N7: 0.95 | O7: =ROUND(J7*L7/2+NORMSINV(N7)*M7*SQRT(J7+K7),0) -> 305 | P7: =C7 -> 150 | Q7: =P7-O7 -> -155 | R7: =(P7-J7*L7/2)/(M7*SQRT(J7+K7)) -> 0.22666305 | S7: =NORMSDIST((P7-J7*L7/2)/(M7*SQRT(J7+K7))) -> 0.58965712 | T7: =O7/L7 -> 6.0905258 | U7: =P7/L7 -> 2.9953406
I9: CSE
I10: Distributor | J10: Review Period | K10: Leadtime | L10: avg daily demand | M10: sigma demand | N10: svc level target | O10: scientific expected inventory on hand | P10: actual average inventory on hand | Q10: delta | R10: imputed z | S10: imputed service | T10: scientific forward days of supply | U10: actual forward days of supply
I11: BOS | J11: 1 | K11: 1 | L11: ='CSE Report'!E97 -> 50.277778 | M11: ='CSE Report'!E98 -> 37.607681 | N11: 0.95 | O11: =ROUND(J11*L11/2+NORMSINV(N11)*M11*SQRT(J11+K11),0) -> 113 | P11: =D4 -> 151 | Q11: =P11-O11 -> 38 | R11: =(P11-J11*L11/2)/(M11*SQRT(J11+K11)) -> 2.3664646 | S11: =NORMSDIST((P11-J11*L11/2)/(M11*SQRT(J11+K11))) -> 0.99102055 | T11: =O11/L11 -> 2.2475138 | U11: =P11/L11 -> 3.0033149
I12: JFK | J12: 2 | K12: 3 | L12: ='CSE Report'!F97 -> 40.277778 | M12: ='CSE Report'!F98 -> 38.76406 | N12: 0.95 | O12: =ROUND(J12*L12/2+NORMSINV(N12)*M12*SQRT(J12+K12),0) -> 183 | P12: =D5 -> 121 | Q12: =P12-O12 -> -62 | R12: =(P12-J12*L12/2)/(M12*SQRT(J12+K12)) -> 0.93127695 | S12: =NORMSDIST((P12-J12*L12/2)/(M12*SQRT(J12+K12))) -> 0.82414484 | T12: =O12/L12 -> 4.5434483 | U12: =P12/L12 -> 3.0041379
I13: LAX | J13: 5 | K13: 5 | L13: ='CSE Report'!D97 -> 18.733333 | M13: ='CSE Report'!D98 -> 14.664641 | N13: 0.95 | O13: =ROUND(J13*L13/2+NORMSINV(N13)*M13*SQRT(J13+K13),0) -> 123 | P13: =D6 -> 56 | Q13: =P13-O13 -> -67 | R13: =(P13-J13*L13/2)/(M13*SQRT(J13+K13)) -> 0.19766966 | S13: =NORMSDIST((P13-J13*L13/2)/(M13*SQRT(J13+K13))) -> 0.57834824 | T13: =O13/L13 -> 6.5658363 | U13: =P13/L13 -> 2.9893238
I14: SFO | J14: 5 | K14: 5 | L14: ='CSE Report'!C97 -> 8.6111111 | M14: ='CSE Report'!C98 -> 7.8678616 | N14: 0.95 | O14: =ROUND(J14*L14/2+NORMSINV(N14)*M14*SQRT(J14+K14),0) -> 62 | P14: =D7 -> 26 | Q14: =P14-O14 -> -36 | R14: =(P14-J14*L14/2)/(M14*SQRT(J14+K14)) -> 0.17974908 | S14: =NORMSDIST((P14-J14*L14/2)/(M14*SQRT(J14+K14))) -> 0.57132522 | T14: =O14/L14 -> 7.2 | U14: =P14/L14 -> 3.0193548

Sheet CSA Report
A1: Last 90 Days of Depletions of SKU CSA at Four Distributors
B3: Day | C3: SFO | D3: LAX | E3: BOS | F3: JFK | H3: CSA
B4: 1 | C4: 26 | D4: 42 | E4: 322 | F4: 12 | H4: 653 | I4: =SUM(C4:F4)/H4 -> 0.61562021
B5: 2 | C5: 18 | D5: 92 | E5: 414 | F5: 192 | H5: 989 | I5: =SUM(C5:F5)/H5 -> 0.7239636
B6: 3 | C6: 83 | D6: 55 | E6: 506 | F6: 94 | H6: 906 | I6: =SUM(C6:F6)/H6 -> 0.81456954
B7: 4 | C7: 27 | D7: 240 | E7: 167 | F7: 41 | H7: 534 | I7: =SUM(C7:F7)/H7 -> 0.88951311
B8: 5 | C8: 36 | D8: 55 | E8: 57 | F8: 253 | H8: 591 | I8: =SUM(C8:F8)/H8 -> 0.678511
B9: 6 | C9: 23 | D9: 70 | E9: 145 | F9: 220 | H9: 654 | I9: =SUM(C9:F9)/H9 -> 0.70030581
B10: 7 | C10: 23 | D10: 57 | E10: 288 | F10: 119 | H10: 696 | I10: =SUM(C10:F10)/H10 -> 0.69971264
B11: 8 | C11: 7 | D11: 5 | E11: 368 | F11: 64 | H11: 544 | I11: =SUM(C11:F11)/H11 -> 0.81617647
B12: 9 | C12: 51 | D12: 44 | E12: 263 | F12: 138 | H12: 689 | I12: =SUM(C12:F12)/H12 -> 0.71988389
B13: 10 | C13: 55 | D13: 1 | E13: 82 | F13: 176 | H13: 610 | I13: =SUM(C13:F13)/H13 -> 0.5147541
B14: 11 | C14: 19 | D14: 56 | E14: 146 | F14: 130 | H14: 511 | I14: =SUM(C14:F14)/H14 -> 0.68688845
B15: 12 | C15: 98 | D15: 123 | E15: 449 | F15: 115 | H15: 983 | I15: =SUM(C15:F15)/H15 -> 0.79857579
... B93: 90 | C93: 96 | D93: 31 | E93: 58 | F93: 611 | H93: 1023 | I93: =SUM(C93:F93)/H93 -> 0.77810362
B95: min | C95: =MIN(C4:C93) -> 2 | D95: =MIN(D4:D93) -> 0 | E95: =MIN(E4:E93) -> 0 | F95: =MIN(F4:F93) -> 12
B96: max | C96: =MAX(C4:C93) -> 170 | D96: =MAX(D4:D93) -> 283 | E96: =MAX(E4:E93) -> 757 | F96: =MAX(F4:F93) -> 611
B97: average | C97: =AVERAGE(C4:C93) -> 50.077778 | D97: =AVERAGE(D4:D93) -> 89.911111 | E97: =AVERAGE(E4:E93) -> 257 | F97: =AVERAGE(F4:F93) -> 157.84444
B98: st dev | C98: =STDEV(C4:C93) -> 34.607341 | D98: =STDEV(D4:D93) -> 65.240376 | E98: =STDEV(E4:E93) -> 142.77853 | F98: =STDEV(F4:F93) -> 97.091167
B99: cv | C99: =C98/C97 -> 0.69107182 | D99: =D98/D97 -> 0.72560971 | E99: =E98/E97 -> 0.55555847 | F99: =F98/F97 -> 0.61510664
B101: Weekly analysis (first 84 days)
B103: Week | C103: SFO | D103: LAX | E103: BOS | F103: JFK
B104: W1 | C104: =SUM(C4:C10) -> 236 | D104: =SUM(D4:D10) -> 611 | E104: =SUM(E4:E10) -> 1899 | F104: =SUM(F4:F10) -> 931
B105: W2 | C105: =SUM(C11:C17) -> 277 | D105: =SUM(D11:D17) -> 292 | E105: =SUM(E11:E17) -> 1703 | F105: =SUM(F11:F17) -> 848
B106: W3 | C106: =SUM(C18:C24) -> 392 | D106: =SUM(D18:D24) -> 617 | E106: =SUM(E18:E24) -> 2057 | F106: =SUM(F18:F24) -> 1257
B107: W4 | C107: =SUM(C25:C31) -> 412 | D107: =SUM(D25:D31) -> 627 | E107: =SUM(E25:E31) -> 1288 | F107: =SUM(F25:F31) -> 1270
B108: W5 | C108: =SUM(C32:C38) -> 328 | D108: =SUM(D32:D38) -> 425 | E108: =SUM(E32:E38) -> 1665 | F108: =SUM(F32:F38) -> 1120
B109: W6 | C109: =SUM(C39:C45) -> 353 | D109: =SUM(D39:D45) -> 692 | E109: =SUM(E39:E45) -> 1952 | F109: =SUM(F39:F45) -> 1125
B110: W7 | C110: =SUM(C46:C52) -> 336 | D110: =SUM(D46:D52) -> 953 | E110: =SUM(E46:E52) -> 1680 | F110: =SUM(F46:F52) -> 1147
B111: W8 | C111: =SUM(C53:C59) -> 405 | D111: =SUM(D53:D59) -> 451 | E111: =SUM(E53:E59) -> 2173 | F111: =SUM(F53:F59) -> 1236
B112: W9 | C112: =SUM(C60:C66) -> 323 | D112: =SUM(D60:D66) -> 458 | E112: =SUM(E60:E66) -> 2156 | F112: =SUM(F60:F66) -> 1125
B113: W10 | C113: =SUM(C67:C73) -> 285 | D113: =SUM(D67:D73) -> 748 | E113: =SUM(E67:E73) -> 1503 | F113: =SUM(F67:F73) -> 932
B114: W11 | C114: =SUM(C74:C80) -> 374 | D114: =SUM(D74:D80) -> 626 | E114: =SUM(E74:E80) -> 1694 | F114: =SUM(F74:F80) -> 858
B115: W12 | C115: =SUM(C81:C87) -> 410 | D115: =SUM(D81:D87) -> 1034 | E115: =SUM(E81:E87) -> 1952 | F115: =SUM(F81:F87) -> 935
B117: min | C117: =MIN(C104:C115) -> 236 | D117: =MIN(D104:D115) -> 292 | E117: =MIN(E104:E115) -> 1288 | F117: =MIN(F104:F115) -> 848
B118: max | C118: =MAX(C104:C115) -> 412 | D118: =MAX(D104:D115) -> 1034 | E118: =MAX(E104:E115) -> 2173 | F118: =MAX(F104:F115) -> 1270
B119: average | C119: =AVERAGE(C104:C115) -> 344.25 | D119: =AVERAGE(D104:D115) -> 627.83333 | E119: =AVERAGE(E104:E115) -> 1810.1667 | F119: =AVERAGE(F104:F115) -> 1065.3333
B120: st dev | C120: =STDEV(C104:C115) -> 57.50909 | D120: =STDEV(D104:D115) -> 213.98931 | E120: =STDEV(E104:E115) -> 268.04099 | F120: =STDEV(F104:F115) -> 155.96056
B121: cv | C121: =C120/C119 -> 0.16705618 | D121: =D120/D119 -> 0.34083776 | E121: =E120/E119 -> 0.14807531 | F121: =F120/F119 -> 0.14639602
B123: Monthly analysis (assumes 30 days per month)
...

Sheet CSE Report
A1: Last 90 Days of Depletions of SKU CSE at Four Distributors
B3: Day | C3: SFO | D3: LAX | E3: BOS | F3: JFK | H3: CSE
B4: 1 | C4: 19 | D4: 3 | E4: 103 | F4: 52 | H4: 343 | I4: =SUM(C4:F4)/H4 -> 0.51603499
B5: 2 | C5: 3 | D5: 7 | E5: 49 | F5: 10 | H5: 84 | I5: =SUM(C5:F5)/H5 -> 0.82142857
B6: 3 | C6: 1 | D6: 2 | E6: 7 | F6: 2 | H6: 22 | I6: =SUM(C6:F6)/H6 -> 0.54545455
B7: 4 | C7: 4 | D7: 11 | E7: 5 | F7: 26 | H7: 69 | I7: =SUM(C7:F7)/H7 -> 0.66666667
B8: 5 | C8: 24 | D8: 14 | E8: 80 | F8: 8 | H8: 223 | I8: =SUM(C8:F8)/H8 -> 0.56502242
B9: 6 | C9: 1 | D9: 5 | E9: 23 | F9: 9 | H9: 64 | I9: =SUM(C9:F9)/H9 -> 0.59375
B10: 7 | C10: 16 | D10: 16 | E10: 27 | F10: 68 | H10: 246 | I10: =SUM(C10:F10)/H10 -> 0.51626016
B11: 8 | C11: 1 | D11: 7 | E11: 60 | F11: 120 | H11: 230 | I11: =SUM(C11:F11)/H11 -> 0.8173913
B12: 9 | C12: 13 | D12: 52 | E12: 23 | F12: 35 | H12: 179 | I12: =SUM(C12:F12)/H12 -> 0.68715084
B13: 10 | C13: 1 | D13: 10 | E13: 27 | F13: 18 | H13: 62 | I13: =SUM(C13:F13)/H13 -> 0.90322581
B14: 11 | C14: 0 | D14: 15 | E14: 31 | F14: 46 | H14: 158 | I14: =SUM(C14:F14)/H14 -> 0.58227848
B15: 12 | C15: 5 | D15: 17 | E15: 72 | F15: 41 | H15: 180 | I15: =SUM(C15:F15)/H15 -> 0.75
... B93: 90 | C93: 16 | D93: 42 | E93: 195 | F93: 10 | H93: 371 | I93: =SUM(C93:F93)/H93 -> 0.70889488
B95: min | C95: =MIN(C4:C93) -> 0 | D95: =MIN(D4:D93) -> 0 | E95: =MIN(E4:E93) -> 0 | F95: =MIN(F4:F93) -> 0
B96: max | C96: =MAX(C4:C93) -> 30 | D96: =MAX(D4:D93) -> 57 | E96: =MAX(E4:E93) -> 195 | F96: =MAX(F4:F93) -> 192
B97: average | C97: =AVERAGE(C4:C93) -> 8.6111111 | D97: =AVERAGE(D4:D93) -> 18.733333 | E97: =AVERAGE(E4:E93) -> 50.277778 | F97: =AVERAGE(F4:F93) -> 40.277778
B98: st dev | C98: =STDEV(C4:C93) -> 7.8678616 | D98: =STDEV(D4:D93) -> 14.664641 | E98: =STDEV(E4:E93) -> 37.607681 | F98: =STDEV(F4:F93) -> 38.76406
B99: cv | C99: =C98/C97 -> 0.91368715 | D99: =D98/D97 -> 0.78281 | E99: =E98/E97 -> 0.74799808 | F99: =F98/F97 -> 0.96241803
B101: Weekly analysis (first 84 days)
B103: Week | C103: SFO | D103: LAX | E103: BOS | F103: JFK
B104: W1 | C104: =SUM(C4:C10) -> 68 | D104: =SUM(D4:D10) -> 58 | E104: =SUM(E4:E10) -> 294 | F104: =SUM(F4:F10) -> 175
B105: W2 | C105: =SUM(C11:C17) -> 38 | D105: =SUM(D11:D17) -> 138 | E105: =SUM(E11:E17) -> 359 | F105: =SUM(F11:F17) -> 311
B106: W3 | C106: =SUM(C18:C24) -> 98 | D106: =SUM(D18:D24) -> 120 | E106: =SUM(E18:E24) -> 397 | F106: =SUM(F18:F24) -> 397
B107: W4 | C107: =SUM(C25:C31) -> 37 | D107: =SUM(D25:D31) -> 139 | E107: =SUM(E25:E31) -> 203 | F107: =SUM(F25:F31) -> 257
B108: W5 | C108: =SUM(C32:C38) -> 83 | D108: =SUM(D32:D38) -> 131 | E108: =SUM(E32:E38) -> 296 | F108: =SUM(F32:F38) -> 317
B109: W6 | C109: =SUM(C39:C45) -> 34 | D109: =SUM(D39:D45) -> 92 | E109: =SUM(E39:E45) -> 239 | F109: =SUM(F39:F45) -> 161
B110: W7 | C110: =SUM(C46:C52) -> 68 | D110: =SUM(D46:D52) -> 178 | E110: =SUM(E46:E52) -> 384 | F110: =SUM(F46:F52) -> 302
B111: W8 | C111: =SUM(C53:C59) -> 44 | D111: =SUM(D53:D59) -> 114 | E111: =SUM(E53:E59) -> 435 | F111: =SUM(F53:F59) -> 320
B112: W9 | C112: =SUM(C60:C66) -> 61 | D112: =SUM(D60:D66) -> 115 | E112: =SUM(E60:E66) -> 392 | F112: =SUM(F60:F66) -> 376
B113: W10 | C113: =SUM(C67:C73) -> 63 | D113: =SUM(D67:D73) -> 156 | E113: =SUM(E67:E73) -> 408 | F113: =SUM(F67:F73) -> 238
B114: W11 | C114: =SUM(C74:C80) -> 54 | D114: =SUM(D74:D80) -> 144 | E114: =SUM(E74:E80) -> 355 | F114: =SUM(F74:F80) -> 348
B115: W12 | C115: =SUM(C81:C87) -> 70 | D115: =SUM(D81:D87) -> 140 | E115: =SUM(E81:E87) -> 365 | F115: =SUM(F81:F87) -> 244
B117: min | C117: =MIN(C104:C115) -> 34 | D117: =MIN(D104:D115) -> 58 | E117: =MIN(E104:E115) -> 203 | F117: =MIN(F104:F115) -> 161
B118: max | C118: =MAX(C104:C115) -> 98 | D118: =MAX(D104:D115) -> 178 | E118: =MAX(E104:E115) -> 435 | F118: =MAX(F104:F115) -> 397
B119: average | C119: =AVERAGE(C104:C115) -> 59.833333 | D119: =AVERAGE(D104:D115) -> 127.08333 | E119: =AVERAGE(E104:E115) -> 343.91667 | F119: =AVERAGE(F104:F115) -> 287.16667
B120: st dev | C120: =STDEV(C104:C115) -> 19.520774 | D120: =STDEV(D104:D115) -> 30.938233 | E120: =STDEV(E104:E115) -> 71.086961 | F120: =STDEV(F104:F115) -> 73.91744
B121: cv | C121: =C120/C119 -> 0.32625249 | D121: =D120/D119 -> 0.24344839 | E121: =E120/E119 -> 0.20669822 | F121: =F120/F119 -> 0.25740258
B123: Monthly analysis (assumes 30 days per month)
...
