Workbook
Name Flow0.: 'Planning Model'!#REF!
Name Flow0._1: 'Planning Model'!$B$12:$V$20
Name Flow0._2: 'Planning Model'!$AB$12:$AX$20
Name Flow0._3: 'Planning Model'!$AC$82:$AX$90
Name Flow1._1: 'Planning Model'!$B$25:$V$75
Name Flow2._1: 'Planning Model'!$A$135:$V$189

Sheet Planning Model
A1: Revenue | E1: =SUMPRODUCT(E317:V344,E255:V282) -> 35125544 | H1: Yellow Cells | J1: model inputs
A2: Production cost | E2: =SUMPRODUCT(E230:V237,E241:V248) -> 20064800 | H2: Green Cells | J2: model decisions variables
A3: Inventory Holding Cost at sources | E3: =SUM(AY13:AY20) -> 8903.3991 | H3: Tan Cells | J3: model intermediate variables,as determined by the decision variabiles and the inputs
A4: Inventory Holding costs at regions | E4: =SUM(AY58:AY71) -> 104706.81
A5: Transportation Cost: Source to Storage | E5: =SUM(W26:W75) -> 8610594.3
A6: Transportation Cost: Buffer to Storage | E6: =SUM(W81:W130) -> 700050.17
A7: Transshipment Cost: Storage to Region | E7: =SUM(W136:W189) -> 1032887.6
A9: Net profit | E9: =E1-SUM(E2:E7) -> 4603601
A11: Flow from source to buffer location | AB11: Inventory at Buffer locations;
A12: Product | B12: SourceID | E12: Mar 21 | F12: Apr 21 | G12: May 21 | H12: Jun 21 | I12: Jul 21 | J12: Aug 21 | K12: Sep 21 | L12: Oct 21 | M12: Nov 21 | N12: Dec 21 | O12: Jan 22 | P12: Feb 22 | Q12: Mar 22 | R12: Apr 22 | S12: May 22 | T12: Jun 22 | U12: Jul 22 | V12: Aug 22 | AB12: Product | AC12: SourceID | AD12: Capacity (tons) | AE12: Monthly Cost/Ton | AF12: 44236 | AG12: Mar 21 | AH12: Apr 21 | AI12: May 21 | AJ12: Jun 21 | AK12: Jul 21 | AL12: Aug 21 | AM12: Sep 21 | AN12: Oct 21 | AO12: Nov 21 | AP12: Dec 21 | AQ12: Jan 22 | AR12: Feb 22 | AS12: Mar 22 | AT12: Apr 22 | AU12: May 22 | AV12: Jun 22 | AW12: Jul 22 | AX12: Aug 22 | AY12: total cost
A13: SW | B13: ARGT | E13: 100 | F13: 0 | G13: 0 | H13: 0 | I13: 0 | J13: 0 | K13: 0 | L13: 0 | M13: 100 | N13: 0 | O13: 0 | P13: 0 | Q13: 0 | R13: 0 | S13: 0 | T13: 0 | U13: 0 | V13: 0 | AB13: SW | AC13: ARGT | AD13: 100 | AE13: 0.33333333 | AF13: 0 | AG13: =AF13+E13-SUM('Planning Model'!E81:E84) -> 100 | AH13: =AG13+F13-SUM('Planning Model'!F81:F84) -> 100 | AI13: =AH13+G13-SUM('Planning Model'!G81:G84) -> 100 | AJ13: =AI13+H13-SUM('Planning Model'!H81:H84) -> 100 | AK13: =AJ13+I13-SUM('Planning Model'!I81:I84) -> 100 | AL13: =AK13+J13-SUM('Planning Model'!J81:J84) -> 100 | AM13: =AL13+K13-SUM('Planning Model'!K81:K84) -> 0 | AN13: =AM13+L13-SUM('Planning Model'!L81:L84) -> 0 | ... AX13: =AW13+V13-SUM('Planning Model'!V81:V84) -> 0 | AY13: =AE13*SUM(AG13:AX13) -> 500
A14: SW | B14: CRTH | E14: 200 | F14: 0 | G14: 0 | H14: 0 | I14: 0 | J14: 0 | K14: 0 | L14: 0 | M14: 0 | N14: 56.17584 | O14: 56.17584 | P14: 87.64832 | Q14: 0 | R14: 0 | S14: 0 | T14: 0 | U14: 0 | V14: 0 | AB14: SW | AC14: CRTH | AD14: 200 | AE14: 0.16666667 | AF14: 0 | AG14: =AF14+'Planning Model'!E14-SUM('Planning Model'!E85:E89) -> 200 | AH14: =AG14+'Planning Model'!F14-SUM('Planning Model'!F85:F89) -> 200 | AI14: =AH14+'Planning Model'!G14-SUM('Planning Model'!G85:G89) -> 200 | AJ14: =AI14+'Planning Model'!H14-SUM('Planning Model'!H85:H89) -> 200 | AK14: =AJ14+'Planning Model'!I14-SUM('Planning Model'!I85:I89) -> 200 | AL14: =AK14+'Planning Model'!J14-SUM('Planning Model'!J85:J89) -> 200 | AM14: =AL14+'Planning Model'!K14-SUM('Planning Model'!K85:K89) -> 200 | AN14: =AM14+'Planning Model'!L14-SUM('Planning Model'!L85:L89) -> 0 | ... AX14: =AW14+'Planning Model'!V14-SUM('Planning Model'!V85:V89) -> 0 | AY14: =AE14*SUM(AG14:AX14) -> 461.42125
A15: HW | B15: HASS | E15: 99.126 | F15: 184.34752 | G15: 162.66685 | H15: 53.859628 | I15: 0 | J15: 0 | K15: 0 | L15: 0 | M15: 82.005766 | N15: 0 | O15: 0 | P15: 0 | Q15: 0 | R15: 0 | S15: 0 | T15: 0 | U15: 0 | V15: 0 | AB15: HW | AC15: HASS | AD15: 500 | AE15: 0.16666667 | AF15: 0 | AG15: =AF15+'Planning Model'!E15-SUM('Planning Model'!E90:E97) -> 99.126 | AH15: =AG15+'Planning Model'!F15-SUM('Planning Model'!F90:F97) -> 283.47352 | AI15: =AH15+'Planning Model'!G15-SUM('Planning Model'!G90:G97) -> 446.14037 | AJ15: =AI15+'Planning Model'!H15-SUM('Planning Model'!H90:H97) -> 500 | AK15: =AJ15+'Planning Model'!I15-SUM('Planning Model'!I90:I97) -> 500 | AL15: =AK15+'Planning Model'!J15-SUM('Planning Model'!J90:J97) -> 500 | AM15: =AL15+'Planning Model'!K15-SUM('Planning Model'!K90:K97) -> 500 | AN15: =AM15+'Planning Model'!L15-SUM('Planning Model'!L90:L97) -> 417.99423 | ... AX15: =AW15+'Planning Model'!V15-SUM('Planning Model'!V90:V97) -> -1.9999999e-06 | AY15: =AE15*SUM(AG15:AX15) -> 1269.3903
A16: HW | B16: JAFF | E16: 100 | F16: 0 | G16: 0 | H16: 0 | I16: 0 | J16: 0 | K16: 0 | L16: 0 | M16: 0 | N16: 0 | O16: 0 | P16: 0 | Q16: 100 | R16: 0 | S16: 0 | T16: 0 | U16: 0 | V16: 0 | AB16: HW | AC16: JAFF | AD16: 100 | AE16: 0.33333333 | AF16: 0 | AG16: =AF16+'Planning Model'!E16-SUM('Planning Model'!E98:E101) -> 100 | AH16: =AG16+'Planning Model'!F16-SUM('Planning Model'!F98:F101) -> 100 | AI16: =AH16+'Planning Model'!G16-SUM('Planning Model'!G98:G101) -> 100 | AJ16: =AI16+'Planning Model'!H16-SUM('Planning Model'!H98:H101) -> 100 | AK16: =AJ16+'Planning Model'!I16-SUM('Planning Model'!I98:I101) -> 100 | AL16: =AK16+'Planning Model'!J16-SUM('Planning Model'!J98:J101) -> 100 | AM16: =AL16+'Planning Model'!K16-SUM('Planning Model'!K98:K101) -> 100 | AN16: =AM16+'Planning Model'!L16-SUM('Planning Model'!L98:L101) -> 100 | ... AX16: =AW16+'Planning Model'!V16-SUM('Planning Model'!V98:V101) -> 0 | AY16: =AE16*SUM(AG16:AX16) -> 482.38337
A17: HW | B17: MICH | E17: 90 | F17: 10 | G17: 0 | H17: 0 | I17: 0 | J17: 0 | K17: 0 | L17: 0 | M17: 0 | N17: 0 | O17: 0 | P17: 100 | Q17: 0 | R17: 0 | S17: 0 | T17: 0 | U17: 0 | V17: 0 | AB17: HW | AC17: MICH | AD17: 100 | AE17: 0.25 | AF17: 0 | AG17: =AF17+'Planning Model'!E17-SUM('Planning Model'!E102:E103) -> 90 | AH17: =AG17+'Planning Model'!F17-SUM('Planning Model'!F102:F103) -> 100 | AI17: =AH17+'Planning Model'!G17-SUM('Planning Model'!G102:G103) -> 100 | AJ17: =AI17+'Planning Model'!H17-SUM('Planning Model'!H102:H103) -> 100 | AK17: =AJ17+'Planning Model'!I17-SUM('Planning Model'!I102:I103) -> 100 | AL17: =AK17+'Planning Model'!J17-SUM('Planning Model'!J102:J103) -> 100 | AM17: =AL17+'Planning Model'!K17-SUM('Planning Model'!K102:K103) -> 100 | AN17: =AM17+'Planning Model'!L17-SUM('Planning Model'!L102:L103) -> 100 | ... AX17: =AW17+'Planning Model'!V17-SUM('Planning Model'!V102:V103) -> 0 | AY17: =AE17*SUM(AG17:AX17) -> 347.5
A18: SW | B18: PRIN | E18: 450 | F18: 450 | G18: 100 | H18: 0 | I18: 0 | J18: 0 | K18: 0 | L18: 0 | M18: 0 | N18: 0 | O18: 0 | P18: 0 | Q18: 0 | R18: 588.41401 | S18: 411.58599 | T18: 0 | U18: 0 | V18: 0 | AB18: SW | AC18: PRIN | AD18: 1000 | AE18: 0.25 | AF18: 0 | AG18: =AF18+E18-SUM('Planning Model'!E104:E114) -> 450 | AH18: =AG18+F18-SUM('Planning Model'!F104:F114) -> 900 | AI18: =AH18+G18-SUM('Planning Model'!G104:G114) -> 1000 | AJ18: =AI18+H18-SUM('Planning Model'!H104:H114) -> 1000 | AK18: =AJ18+I18-SUM('Planning Model'!I104:I114) -> 1000 | AL18: =AK18+J18-SUM('Planning Model'!J104:J114) -> 1000 | AM18: =AL18+K18-SUM('Planning Model'!K104:K114) -> 663.00035 | AN18: =AM18+L18-SUM('Planning Model'!L104:L114) -> 345.15619 | ... AX18: =AW18+V18-SUM('Planning Model'!V104:V114) -> 2e-06 | AY18: =AE18*SUM(AG18:AX18) -> 2543.9391
A19: HW | B19: SCHY | E19: 100 | F19: 0 | G19: 0 | H19: 0 | I19: 0 | J19: 0 | K19: 0 | L19: 0 | M19: 100 | N19: 0 | O19: 0 | P19: 0 | Q19: 0 | R19: 100 | S19: 0 | T19: 0 | U19: 0 | V19: 0 | AB19: HW | AC19: SCHY | AD19: 100 | AE19: 0.16666667 | AF19: 0 | AG19: =AF19+E19-SUM('Planning Model'!E115:E121) -> 100 | AH19: =AG19+F19-SUM('Planning Model'!F115:F121) -> 100 | AI19: =AH19+G19-SUM('Planning Model'!G115:G121) -> 100 | AJ19: =AI19+H19-SUM('Planning Model'!H115:H121) -> 100 | AK19: =AJ19+I19-SUM('Planning Model'!I115:I121) -> 100 | AL19: =AK19+J19-SUM('Planning Model'!J115:J121) -> 100 | AM19: =AL19+K19-SUM('Planning Model'!K115:K121) -> 100 | AN19: =AM19+L19-SUM('Planning Model'!L115:L121) -> 0 | ... AX19: =AW19+V19-SUM('Planning Model'!V115:V121) -> 0 | AY19: =AE19*SUM(AG19:AX19) -> 250
A20: SW | B20: STFC | E20: 1000 | F20: 0 | G20: 0 | H20: 0 | I20: 0 | J20: 0 | K20: 0 | L20: 0 | M20: 0 | N20: 22.199177 | O20: 287.09685 | P20: 408.34185 | Q20: 282.36212 | R20: 0 | S20: 0 | T20: 0 | U20: 0 | V20: 0 | AB20: SW | AC20: STFC | AD20: 1000 | AE20: 0.25 | AF20: 0 | AG20: =AF20+E20-SUM('Planning Model'!E122:E130) -> 1000 | AH20: =AG20+F20-SUM('Planning Model'!F122:F130) -> 1000 | AI20: =AH20+G20-SUM('Planning Model'!G122:G130) -> 1000 | AJ20: =AI20+H20-SUM('Planning Model'!H122:H130) -> 1000 | AK20: =AJ20+I20-SUM('Planning Model'!I122:I130) -> 1000 | AL20: =AK20+J20-SUM('Planning Model'!J122:J130) -> 1000 | AM20: =AL20+K20-SUM('Planning Model'!K122:K130) -> 145.92717 | AN20: =AM20+L20-SUM('Planning Model'!L122:L130) -> 0 | ... AX20: =AW20+V20-SUM('Planning Model'!V122:V130) -> -2.9999999e-06 | AY20: =AE20*SUM(AG20:AX20) -> 3048.7651
A24: Flow from source to depot storage points | AB24: Inventory at depot storage points
B25: SourceID | C25: StorID | D25: Cost/ton | E25: Mar 21 | F25: Apr 21 | G25: May 21 | H25: Jun 21 | I25: Jul 21 | J25: Aug 21 | K25: Sep 21 | L25: Oct 21 | M25: Nov 21 | N25: Dec 21 | O25: Jan 22 | P25: Feb 22 | Q25: Mar 22 | R25: Apr 22 | S25: May 22 | T25: Jun 22 | U25: Jul 22 | V25: Aug 22 | W25: Total Cost | AB25: Product | AC25: regionID | AF25: 44236 | AG25: Mar 21 | AH25: Apr 21 | AI25: May 21 | AJ25: Jun 21 | AK25: Jul 21 | AL25: Aug 21 | AM25: Sep 21 | AN25: Oct 21 | AO25: Nov 21 | AP25: Dec 21 | AQ25: Jan 22 | AR25: Feb 22 | AS25: Mar 22 | AT25: Apr 22 | AU25: May 22 | AV25: Jun 22 | AW25: Jul 22 | AX25: Aug 22
A26: SW | B26: ARGT | C26: CJER | D26: 58.333333 | E26: 850.5 | F26: 0 | G26: 0 | H26: 0 | I26: 0 | J26: 0 | K26: 0 | L26: 0 | M26: 0 | N26: 0 | O26: 0 | P26: 0 | Q26: 0 | R26: 0 | S26: 0 | T26: 0 | U26: 0 | V26: 0 | W26: =D26*SUM(E26:V26) -> 49612.5 | AB26: HW | AC26: BERK | AF26: 300 | AG26: =AF26+'Planning Model'!E43+'Planning Model'!E98+'Planning Model'!E60+'Planning Model'!E115-'Planning Model'!E137 -> 284.17531 | AH26: =AG26+'Planning Model'!F43+'Planning Model'!F98+'Planning Model'!F60+'Planning Model'!F115-'Planning Model'!F137 -> 814.93398 | AI26: =AH26+'Planning Model'!G43+'Planning Model'!G98+'Planning Model'!G60+'Planning Model'!G115-'Planning Model'!G137 -> 949.99999 | AJ26: =AI26+'Planning Model'!H43+'Planning Model'!H98+'Planning Model'!H60+'Planning Model'!H115-'Planning Model'!H137 -> 788.23489 | AK26: =AJ26+'Planning Model'!I43+'Planning Model'!I98+'Planning Model'!I60+'Planning Model'!I115-'Planning Model'!I137 -> 647.26452 | AL26: =AK26+'Planning Model'!J43+'Planning Model'!J98+'Planning Model'!J60+'Planning Model'!J115-'Planning Model'!J137 -> 509.83435 | AM26: =AL26+'Planning Model'!K43+'Planning Model'!K98+'Planning Model'!K60+'Planning Model'!K115-'Planning Model'!K137 -> 296.97546 | AN26: =AM26+'Planning Model'!L43+'Planning Model'!L98+'Planning Model'!L60+'Planning Model'!L115-'Planning Model'!L137 -> 83.733852 | ... AX26: =AW26+'Planning Model'!V43+'Planning Model'!V98+'Planning Model'!V60+'Planning Model'!V115-'Planning Model'!V137 -> -1.6999999e-06
A27: SW | B27: ARGT | C27: HUDV | D27: 41.666667 | E27: 49.5 | F27: 1000 | G27: 635.85506 | H27: 985.7295 | I27: 798.51655 | J27: 292.46568 | K27: 788.05632 | L27: 842.84018 | M27: 878.19557 | N27: 162.18707 | O27: 162.18707 | P27: 371.08529 | Q27: 455.34875 | R27: 1390.5406 | S27: 1255.5663 | T27: 1256.8051 | U27: 883.59365 | V27: 682.81785 | W27: =D27*SUM(E27:V27) -> 537137.11 | AB27: HW | AC27: CJER | AF27: 0 | AG27: =AF27+'Planning Model'!E35+'Planning Model'!E61+'Planning Model'!E90+'Planning Model'!E116-'Planning Model'!E138 -> 109.62 | AH27: =AG27+'Planning Model'!F35+'Planning Model'!F61+'Planning Model'!F90+'Planning Model'!F116-'Planning Model'!F138 -> 105.84 | AI27: =AH27+'Planning Model'!G35+'Planning Model'!G61+'Planning Model'!G90+'Planning Model'!G116-'Planning Model'!G138 -> 100.17 | AJ27: =AI27+'Planning Model'!H35+'Planning Model'!H61+'Planning Model'!H90+'Planning Model'!H116-'Planning Model'!H138 -> 97.335 | AK27: =AJ27+'Planning Model'!I35+'Planning Model'!I61+'Planning Model'!I90+'Planning Model'!I116-'Planning Model'!I138 -> 92.61 | AL27: =AK27+'Planning Model'!J35+'Planning Model'!J61+'Planning Model'!J90+'Planning Model'!J116-'Planning Model'!J138 -> 86.94 | AM27: =AL27+'Planning Model'!K35+'Planning Model'!K61+'Planning Model'!K90+'Planning Model'!K116-'Planning Model'!K138 -> 77.49 | AN27: =AM27+'Planning Model'!L35+'Planning Model'!L61+'Planning Model'!L90+'Planning Model'!L116-'Planning Model'!L138 -> 63.315 | ... AX27: =AW27+'Planning Model'!V35+'Planning Model'!V61+'Planning Model'!V90+'Planning Model'!V116-'Planning Model'!V138 -> 1.2878587e-14
A28: SW | B28: ARGT | C28: NJER | D28: 41.666667 | E28: 0 | F28: 0 | G28: 227.37625 | H28: 0 | I28: 201.48345 | J28: 241.542 | K28: 285.00255 | L28: 371.58345 | M28: 160.14915 | N28: 107.24805 | O28: 107.24805 | P28: 85.79844 | Q28: 44.65125 | R28: 109.45935 | S28: 244.4337 | T28: 243.19489 | U28: 301.55036 | V28: 362.313 | W28: =D28*SUM(E28:V28) -> 128876.41 | AB28: HW | AC28: CTRI | AF28: 0 | AG28: =AF28-'Planning Model'!E139-'Planning Model'!E143-'Planning Model'!E152-'Planning Model'!E159 -> 0 | AH28: =AG28-'Planning Model'!F139-'Planning Model'!F143-'Planning Model'!F152-'Planning Model'!F159 -> 0 | AI28: =AH28-'Planning Model'!G139-'Planning Model'!G143-'Planning Model'!G152-'Planning Model'!G159 -> 0 | AJ28: =AI28-'Planning Model'!H139-'Planning Model'!H143-'Planning Model'!H152-'Planning Model'!H159 -> 0 | AK28: =AJ28-'Planning Model'!I139-'Planning Model'!I143-'Planning Model'!I152-'Planning Model'!I159 -> 0 | AL28: =AK28-'Planning Model'!J139-'Planning Model'!J143-'Planning Model'!J152-'Planning Model'!J159 -> 0 | AM28: =AL28-'Planning Model'!K139-'Planning Model'!K143-'Planning Model'!K152-'Planning Model'!K159 -> 0 | AN28: =AM28-'Planning Model'!L139-'Planning Model'!L143-'Planning Model'!L152-'Planning Model'!L159 -> 0 | ... AX28: =AW28-'Planning Model'!V139-'Planning Model'!V143-'Planning Model'!V152-'Planning Model'!V159 -> 0
A29: SW | B29: ARGT | C29: WTCT | D29: 50 | E29: 0 | F29: 0 | G29: 136.76869 | H29: 14.2705 | I29: 0 | J29: 965.99232 | K29: 426.94113 | L29: 285.57637 | M29: 361.65528 | N29: 230.56488 | O29: 230.56488 | P29: 43.116272 | Q29: 0 | R29: 0 | S29: 0 | T29: 0 | U29: 314.85599 | V29: 954.86915 | W29: =D29*SUM(E29:V29) -> 198258.77 | AB29: HW | AC29: DEME | AF29: 0 | AG29: =AF29-'Planning Model'!E140 -> 0 | AH29: =AG29-'Planning Model'!F140 -> 0 | AI29: =AH29-'Planning Model'!G140 -> 0 | AJ29: =AI29-'Planning Model'!H140 -> 0 | AK29: =AJ29-'Planning Model'!I140 -> 0 | AL29: =AK29-'Planning Model'!J140 -> 0 | AM29: =AL29-'Planning Model'!K140 -> 0 | AN29: =AM29-'Planning Model'!L140 -> 0 | ... AX29: =AW29-'Planning Model'!V140 -> 0
A30: SW | B30: CRTH | C30: DEME | D30: 41.666667 | E30: 0 | F30: 0 | G30: 0 | H30: 0 | I30: 0 | J30: 0 | K30: 0 | L30: 0 | M30: 0 | N30: 0 | O30: 0 | P30: 0 | Q30: 0 | R30: 0 | S30: 0 | T30: 0 | U30: 0 | V30: 0 | W30: =D30*SUM(E30:V30) -> 0 | AB30: HW | AC30: HUDV | AF30: 300 | AG30: =AF30+'Planning Model'!E36+'Planning Model'!E62+'Planning Model'!E91+'Planning Model'!E117-'Planning Model'!E142 -> 723.68719 | AH30: =AG30+'Planning Model'!F36+'Planning Model'!F62+'Planning Model'!F91+'Planning Model'!F117-'Planning Model'!F142 -> 646.26511 | AI30: =AH30+'Planning Model'!G36+'Planning Model'!G62+'Planning Model'!G91+'Planning Model'!G117-'Planning Model'!G142 -> 550.88685 | AJ30: =AI30+'Planning Model'!H36+'Planning Model'!H62+'Planning Model'!H91+'Planning Model'!H117-'Planning Model'!H142 -> 403.02743 | AK30: =AJ30+'Planning Model'!I36+'Planning Model'!I62+'Planning Model'!I91+'Planning Model'!I117-'Planning Model'!I142 -> 308.57941 | AL30: =AK30+'Planning Model'!J36+'Planning Model'!J62+'Planning Model'!J91+'Planning Model'!J117-'Planning Model'!J142 -> 121.88934 | AM30: =AL30+'Planning Model'!K36+'Planning Model'!K62+'Planning Model'!K91+'Planning Model'!K117-'Planning Model'!K142 -> 1.2e-05 | AN30: =AM30+'Planning Model'!L36+'Planning Model'!L62+'Planning Model'!L91+'Planning Model'!L117-'Planning Model'!L142 -> 1.5e-05 | ... AX30: =AW30+'Planning Model'!V36+'Planning Model'!V62+'Planning Model'!V91+'Planning Model'!V117-'Planning Model'!V142 -> 1.9e-05
A31: SW | B31: CRTH | C31: NCMA | D31: 58.333333 | E31: 0 | F31: 0 | G31: 0 | H31: 0 | I31: 0 | J31: 0 | K31: 0 | L31: 0 | M31: 0 | N31: 0 | O31: 0 | P31: 0 | Q31: 0 | R31: 0 | S31: 0 | T31: 0 | U31: 0 | V31: 0 | W31: =D31*SUM(E31:V31) -> 0 | AB31: HW | AC31: NCMA | AF31: 250 | AG31: =AF31+'Planning Model'!E37+'Planning Model'!E63+'Planning Model'!E92+'Planning Model'!E118-'Planning Model'!E146 -> 199.4425 | AH31: =AG31+'Planning Model'!F37+'Planning Model'!F63+'Planning Model'!F92+'Planning Model'!F118-'Planning Model'!F146 -> 70.9603 | AI31: =AH31+'Planning Model'!G37+'Planning Model'!G63+'Planning Model'!G92+'Planning Model'!G118-'Planning Model'!G146 -> 8.05011 | AJ31: =AI31+'Planning Model'!H37+'Planning Model'!H63+'Planning Model'!H92+'Planning Model'!H118-'Planning Model'!H146 -> 104.16641 | AK31: =AJ31+'Planning Model'!I37+'Planning Model'!I63+'Planning Model'!I92+'Planning Model'!I118-'Planning Model'!I146 -> 0 | AL31: =AK31+'Planning Model'!J37+'Planning Model'!J63+'Planning Model'!J92+'Planning Model'!J118-'Planning Model'!J146 -> 0 | AM31: =AL31+'Planning Model'!K37+'Planning Model'!K63+'Planning Model'!K92+'Planning Model'!K118-'Planning Model'!K146 -> 0 | AN31: =AM31+'Planning Model'!L37+'Planning Model'!L63+'Planning Model'!L92+'Planning Model'!L118-'Planning Model'!L146 -> 3e-06 | ... AX31: =AW31+'Planning Model'!V37+'Planning Model'!V63+'Planning Model'!V92+'Planning Model'!V118-'Planning Model'!V146 -> 9.9999997e-06
A32: SW | B32: CRTH | C32: SCST | D32: 50 | E32: 0 | F32: 315 | G32: 315 | H32: 315 | I32: 315 | J32: 315 | K32: 315 | L32: 315 | M32: 315 | N32: 258.82416 | O32: 258.82416 | P32: 207.05933 | Q32: 99.792 | R32: 654.2046 | S32: 1050 | T32: 1050 | U32: 1050 | V32: 1050 | W32: =D32*SUM(E32:V32) -> 409935.21 | AB32: HW | AC32: NJER | AF32: 50 | AG32: =AF32+'Planning Model'!E38+'Planning Model'!E64+'Planning Model'!E93+'Planning Model'!E119-'Planning Model'!E147 -> 46.6925 | AH32: =AG32+'Planning Model'!F38+'Planning Model'!F64+'Planning Model'!F93+'Planning Model'!F119-'Planning Model'!F147 -> 38.5844 | AI32: =AH32+'Planning Model'!G38+'Planning Model'!G64+'Planning Model'!G93+'Planning Model'!G119-'Planning Model'!G147 -> 20.4782 | AJ32: =AI32+'Planning Model'!H38+'Planning Model'!H64+'Planning Model'!H93+'Planning Model'!H119-'Planning Model'!H147 -> 2.51375 | AK32: =AJ32+'Planning Model'!I38+'Planning Model'!I64+'Planning Model'!I93+'Planning Model'!I119-'Planning Model'!I147 -> 0 | AL32: =AK32+'Planning Model'!J38+'Planning Model'!J64+'Planning Model'!J93+'Planning Model'!J119-'Planning Model'!J147 -> 0 | AM32: =AL32+'Planning Model'!K38+'Planning Model'!K64+'Planning Model'!K93+'Planning Model'!K119-'Planning Model'!K147 -> 0 | AN32: =AM32+'Planning Model'!L38+'Planning Model'!L64+'Planning Model'!L93+'Planning Model'!L119-'Planning Model'!L147 -> 0 | ... AX32: =AW32+'Planning Model'!V38+'Planning Model'!V64+'Planning Model'!V93+'Planning Model'!V119-'Planning Model'!V147 -> 0
A33: SW | B33: CRTH | C33: SEMA | D33: 66.666667 | E33: 0 | F33: 0 | G33: 0 | H33: 0 | I33: 0 | J33: 0 | K33: 0 | L33: 0 | M33: 0 | N33: 0 | O33: 0 | P33: 0 | Q33: 0 | R33: 0 | S33: 0 | T33: 0 | U33: 0 | V33: 0 | W33: =D33*SUM(E33:V33) -> 0 | AB33: HW | AC33: OHIO | AF33: 200 | AG33: =AF33+'Planning Model'!E39+'Planning Model'!E47+'Planning Model'!E94+'Planning Model'!E102-'Planning Model'!E148 -> 195.1805 | AH33: =AG33+'Planning Model'!F39+'Planning Model'!F47+'Planning Model'!F94+'Planning Model'!F102-'Planning Model'!F148 -> 189.80534 | AI33: =AH33+'Planning Model'!G39+'Planning Model'!G47+'Planning Model'!G94+'Planning Model'!G102-'Planning Model'!G148 -> 185.56985 | AJ33: =AI33+'Planning Model'!H39+'Planning Model'!H47+'Planning Model'!H94+'Planning Model'!H102-'Planning Model'!H148 -> 180.10113 | AK33: =AJ33+'Planning Model'!I39+'Planning Model'!I47+'Planning Model'!I94+'Planning Model'!I102-'Planning Model'!I148 -> 172.33607 | AL33: =AK33+'Planning Model'!J39+'Planning Model'!J47+'Planning Model'!J94+'Planning Model'!J102-'Planning Model'!J148 -> 162.96356 | AM33: =AL33+'Planning Model'!K39+'Planning Model'!K47+'Planning Model'!K94+'Planning Model'!K102-'Planning Model'!K148 -> 154.84979 | AN33: =AM33+'Planning Model'!L39+'Planning Model'!L47+'Planning Model'!L94+'Planning Model'!L102-'Planning Model'!L148 -> 140.37428 | ... AX33: =AW33+'Planning Model'!V39+'Planning Model'!V47+'Planning Model'!V94+'Planning Model'!V102-'Planning Model'!V148 -> 45.230547
A34: SW | B34: CRTH | C34: SONH | D34: 50 | E34: 115 | F34: 0 | G34: 0 | H34: 0 | I34: 0 | J34: 0 | K34: 0 | L34: 0 | M34: 0 | N34: 0 | O34: 0 | P34: 20.292352 | Q34: 215.208 | R34: 395.7954 | S34: 0 | T34: 0 | U34: 0 | V34: 0 | W34: =D34*SUM(E34:V34) -> 37314.788 | AB34: HW | AC34: SCST | AF34: 0 | AG34: =AF34-'Planning Model'!E151 -> 0 | AH34: =AG34-'Planning Model'!F151 -> 0 | AI34: =AH34-'Planning Model'!G151 -> 0 | AJ34: =AI34-'Planning Model'!H151 -> 0 | AK34: =AJ34-'Planning Model'!I151 -> 0 | AL34: =AK34-'Planning Model'!J151 -> 0 | AM34: =AL34-'Planning Model'!K151 -> 0 | AN34: =AM34-'Planning Model'!L151 -> 0 | ... AX34: =AW34-'Planning Model'!V151 -> 0
A35: HW | B35: HASS | C35: CJER | D35: 141.66667 | E35: 113.4 | F35: 0 | G35: 0 | H35: 0 | I35: 0 | J35: 0 | K35: 0 | L35: 0 | M35: 0 | N35: 0 | O35: 0 | P35: 0 | Q35: 0 | R35: 0 | S35: 0 | T35: 0 | U35: 0 | V35: 0 | W35: =D35*SUM(E35:V35) -> 16065 | AB35: HW | AC35: SEMA | AF35: 0 | AG35: =AF35+'Planning Model'!E40+'Planning Model'!E95-'Planning Model'!E154 -> 0 | AH35: =AG35+'Planning Model'!F40+'Planning Model'!F95-'Planning Model'!F154 -> 0 | AI35: =AH35+'Planning Model'!G40+'Planning Model'!G95-'Planning Model'!G154 -> 0 | AJ35: =AI35+'Planning Model'!H40+'Planning Model'!H95-'Planning Model'!H154 -> 92.405332 | AK35: =AJ35+'Planning Model'!I40+'Planning Model'!I95-'Planning Model'!I154 -> 145.64832 | AL35: =AK35+'Planning Model'!J40+'Planning Model'!J95-'Planning Model'!J154 -> 126.1663 | AM35: =AL35+'Planning Model'!K40+'Planning Model'!K95-'Planning Model'!K154 -> 4.194349 | AN35: =AM35+'Planning Model'!L40+'Planning Model'!L95-'Planning Model'!L154 -> -8.0000001e-06 | ... AX35: =AW35+'Planning Model'!V40+'Planning Model'!V95-'Planning Model'!V154 -> -1.7e-05
A36: HW | B36: HASS | C36: HUDV | D36: 161.66667 | E36: 0 | F36: 0 | G36: 0 | H36: 0 | I36: 0 | J36: 0 | K36: 0 | L36: 0 | M36: 0 | N36: 0 | O36: 0 | P36: 0 | Q36: 0 | R36: 0 | S36: 0 | T36: 0 | U36: 0 | V36: 0 | W36: =D36*SUM(E36:V36) -> 0 | AB36: HW | AC36: SONH | AF36: 0 | AG36: =AF36+'Planning Model'!E44+'Planning Model'!E99-'Planning Model'!E157 -> 105.825 | AH36: =AG36+'Planning Model'!F44+'Planning Model'!F99-'Planning Model'!F157 -> 292.88514 | AI36: =AH36+'Planning Model'!G44+'Planning Model'!G99-'Planning Model'!G157 -> 512.88514 | AJ36: =AI36+'Planning Model'!H44+'Planning Model'!H99-'Planning Model'!H157 -> 473.0481 | AK36: =AJ36+'Planning Model'!I44+'Planning Model'!I99-'Planning Model'!I157 -> 166.97983 | AL36: =AK36+'Planning Model'!J44+'Planning Model'!J99-'Planning Model'!J157 -> 293.72251 | AM36: =AL36+'Planning Model'!K44+'Planning Model'!K99-'Planning Model'!K157 -> 1.4e-05 | AN36: =AM36+'Planning Model'!L44+'Planning Model'!L99-'Planning Model'!L157 -> 1.4e-05 | ... AX36: =AW36+'Planning Model'!V44+'Planning Model'!V99-'Planning Model'!V157 -> 1.4e-05
A37: HW | B37: HASS | C37: NCMA | D37: 175 | E37: 0 | F37: 0 | G37: 0 | H37: 0 | I37: 0 | J37: 48.7333 | K37: 114.166 | L37: 27.842203 | M37: 0 | N37: 77.5656 | O37: 77.5656 | P37: 62.05248 | Q37: 75.83625 | R37: 0 | S37: 102.86755 | T37: 98.759131 | U37: 191.41942 | V37: 184.743 | W37: =D37*SUM(E37:V37) -> 185771.34 | AB37: HW | AC37: UVLY | AF37: 0 | AG37: =AF37+'Planning Model'!E45+'Planning Model'!E100-'Planning Model'!E155-'Planning Model'!E149-'Planning Model'!E144-'Planning Model'!E158 -> 0 | AH37: =AG37+'Planning Model'!F45+'Planning Model'!F100-'Planning Model'!F155-'Planning Model'!F149-'Planning Model'!F144-'Planning Model'!F158 -> 0 | AI37: =AH37+'Planning Model'!G45+'Planning Model'!G100-'Planning Model'!G155-'Planning Model'!G149-'Planning Model'!G144-'Planning Model'!G158 -> 0 | AJ37: =AI37+'Planning Model'!H45+'Planning Model'!H100-'Planning Model'!H155-'Planning Model'!H149-'Planning Model'!H144-'Planning Model'!H158 -> 0 | AK37: =AJ37+'Planning Model'!I45+'Planning Model'!I100-'Planning Model'!I155-'Planning Model'!I149-'Planning Model'!I144-'Planning Model'!I158 -> 0 | AL37: =AK37+'Planning Model'!J45+'Planning Model'!J100-'Planning Model'!J155-'Planning Model'!J149-'Planning Model'!J144-'Planning Model'!J158 -> 0 | AM37: =AL37+'Planning Model'!K45+'Planning Model'!K100-'Planning Model'!K155-'Planning Model'!K149-'Planning Model'!K144-'Planning Model'!K158 -> 74.96656 | AN37: =AM37+'Planning Model'!L45+'Planning Model'!L100-'Planning Model'!L155-'Planning Model'!L149-'Planning Model'!L144-'Planning Model'!L158 -> 10.97494 | ... AX37: =AW37+'Planning Model'!V45+'Planning Model'!V100-'Planning Model'!V155-'Planning Model'!V149-'Planning Model'!V144-'Planning Model'!V158 -> -4e-06
A38: HW | B38: HASS | C38: NJER | D38: 150 | E38: 0 | F38: 0 | G38: 0 | H38: 0 | I38: 19.8733 | J38: 26.838 | K38: 31.66695 | L38: 41.28705 | M38: 17.79435 | N38: 11.91645 | O38: 11.91645 | P38: 9.53316 | Q38: 4.96125 | R38: 12.16215 | S38: 27.1593 | T38: 26.946675 | U38: 33.580575 | V38: 40.257 | W38: =D38*SUM(E38:V38) -> 47383.899 | AB38: HW | AC38: WTCT | AF38: 800 | AG38: =AF38+'Planning Model'!E41+'Planning Model'!E65+'Planning Model'!E96+'Planning Model'!E120-'Planning Model'!E161 -> 794.33 | AH38: =AG38+'Planning Model'!F41+'Planning Model'!F65+'Planning Model'!F96+'Planning Model'!F120-'Planning Model'!F161 -> 742.17734 | AI38: =AH38+'Planning Model'!G41+'Planning Model'!G65+'Planning Model'!G96+'Planning Model'!G120-'Planning Model'!G161 -> 665.31482 | AJ38: =AI38+'Planning Model'!H41+'Planning Model'!H65+'Planning Model'!H96+'Planning Model'!H120-'Planning Model'!H161 -> 568.18772 | AK38: =AJ38+'Planning Model'!I41+'Planning Model'!I65+'Planning Model'!I96+'Planning Model'!I120-'Planning Model'!I161 -> 413.49878 | AL38: =AK38+'Planning Model'!J41+'Planning Model'!J65+'Planning Model'!J96+'Planning Model'!J120-'Planning Model'!J161 -> 232.81856 | AM38: =AL38+'Planning Model'!K41+'Planning Model'!K65+'Planning Model'!K96+'Planning Model'!K120-'Planning Model'!K161 -> 29.60576 | AN38: =AM38+'Planning Model'!L41+'Planning Model'!L65+'Planning Model'!L96+'Planning Model'!L120-'Planning Model'!L161 -> 0 | ... AX38: =AW38+'Planning Model'!V41+'Planning Model'!V65+'Planning Model'!V96+'Planning Model'!V120-'Planning Model'!V161 -> 0
A39: HW | B39: HASS | C39: OHIO | D39: 75 | E39: 0 | F39: 0 | G39: 0 | H39: 0 | I39: 0 | J39: 0 | K39: 0 | L39: 0 | M39: 0 | N39: 0 | O39: 0 | P39: 0 | Q39: 0 | R39: 0 | S39: 0 | T39: 0 | U39: 0 | V39: 0 | W39: =D39*SUM(E39:V39) -> 0 | AB39: HW | AC39: WTMA | AF39: 3000 | AG39: =AF39+'Planning Model'!E42+'Planning Model'!E46+'Planning Model'!E48+'Planning Model'!E66+'Planning Model'!E97+'Planning Model'!E101+'Planning Model'!E103+'Planning Model'!E121-'Planning Model'!E136-'Planning Model'!E141-'Planning Model'!E145-'Planning Model'!E150-'Planning Model'!E153-'Planning Model'!E156-'Planning Model'!E160-'Planning Model'!E162 -> 2924.3055 | AH39: =AG39+'Planning Model'!F42+'Planning Model'!F46+'Planning Model'!F48+'Planning Model'!F66+'Planning Model'!F97+'Planning Model'!F101+'Planning Model'!F103+'Planning Model'!F121-'Planning Model'!F136-'Planning Model'!F141-'Planning Model'!F145-'Planning Model'!F150-'Planning Model'!F153-'Planning Model'!F156-'Planning Model'!F160-'Planning Model'!F162 -> 2755.9028 | AI39: =AH39+'Planning Model'!G42+'Planning Model'!G46+'Planning Model'!G48+'Planning Model'!G66+'Planning Model'!G97+'Planning Model'!G101+'Planning Model'!G103+'Planning Model'!G121-'Planning Model'!G136-'Planning Model'!G141-'Planning Model'!G145-'Planning Model'!G150-'Planning Model'!G153-'Planning Model'!G156-'Planning Model'!G160-'Planning Model'!G162 -> 2405.8654 | AJ39: =AI39+'Planning Model'!H42+'Planning Model'!H46+'Planning Model'!H48+'Planning Model'!H66+'Planning Model'!H97+'Planning Model'!H101+'Planning Model'!H103+'Planning Model'!H121-'Planning Model'!H136-'Planning Model'!H141-'Planning Model'!H145-'Planning Model'!H150-'Planning Model'!H153-'Planning Model'!H156-'Planning Model'!H160-'Planning Model'!H162 -> 1917.3646 | AK39: =AJ39+'Planning Model'!I42+'Planning Model'!I46+'Planning Model'!I48+'Planning Model'!I66+'Planning Model'!I97+'Planning Model'!I101+'Planning Model'!I103+'Planning Model'!I121-'Planning Model'!I136-'Planning Model'!I141-'Planning Model'!I145-'Planning Model'!I150-'Planning Model'!I153-'Planning Model'!I156-'Planning Model'!I160-'Planning Model'!I162 -> 1568.1154 | AL39: =AK39+'Planning Model'!J42+'Planning Model'!J46+'Planning Model'!J48+'Planning Model'!J66+'Planning Model'!J97+'Planning Model'!J101+'Planning Model'!J103+'Planning Model'!J121-'Planning Model'!J136-'Planning Model'!J141-'Planning Model'!J145-'Planning Model'!J150-'Planning Model'!J153-'Planning Model'!J156-'Planning Model'!J160-'Planning Model'!J162 -> 903.16624 | AM39: =AL39+'Planning Model'!K42+'Planning Model'!K46+'Planning Model'!K48+'Planning Model'!K66+'Planning Model'!K97+'Planning Model'!K101+'Planning Model'!K103+'Planning Model'!K121-'Planning Model'!K136-'Planning Model'!K141-'Planning Model'!K145-'Planning Model'!K150-'Planning Model'!K153-'Planning Model'!K156-'Planning Model'!K160-'Planning Model'!K162 -> 617.42384 | AN39: =AM39+'Planning Model'!L42+'Planning Model'!L46+'Planning Model'!L48+'Planning Model'!L66+'Planning Model'!L97+'Planning Model'!L101+'Planning Model'!L103+'Planning Model'!L121-'Planning Model'!L136-'Planning Model'!L141-'Planning Model'!L145-'Planning Model'!L150-'Planning Model'!L153-'Planning Model'!L156-'Planning Model'!L160-'Planning Model'!L162 -> 88.23149 | ... AX39: =AW39+'Planning Model'!V42+'Planning Model'!V46+'Planning Model'!V48+'Planning Model'!V66+'Planning Model'!V97+'Planning Model'!V101+'Planning Model'!V103+'Planning Model'!V121-'Planning Model'!V136-'Planning Model'!V141-'Planning Model'!V145-'Planning Model'!V150-'Planning Model'!V153-'Planning Model'!V156-'Planning Model'!V160-'Planning Model'!V162 -> -2.0000004e-06
A40: HW | B40: HASS | C40: SEMA | D40: 156.66667 | E40: 12.474 | F40: 40.652482 | G40: 62.333145 | H40: 171.14037 | I40: 205.1267 | J40: 149.4287 | K40: 79.167047 | L40: 34.983367 | M40: 62.715558 | N40: 128.66975 | O40: 94.83003 | P40: 120.86402 | Q40: 135.6975 | R40: 212.83785 | S40: 94.973155 | T40: 99.294194 | U40: 0 | V40: 0 | W40: =D40*SUM(E40:V40) -> 267146.1 | AB40: SW | AC40: BERK | AF40: 50 | AG40: =AF40+'Planning Model'!E49+'Planning Model'!E104-'Planning Model'!E164 -> 50 | AH40: =AG40+'Planning Model'!F49+'Planning Model'!F104-'Planning Model'!F164 -> 50 | AI40: =AH40+'Planning Model'!G49+'Planning Model'!G104-'Planning Model'!G164 -> 50 | AJ40: =AI40+'Planning Model'!H49+'Planning Model'!H104-'Planning Model'!H164 -> 50 | AK40: =AJ40+'Planning Model'!I49+'Planning Model'!I104-'Planning Model'!I164 -> 0 | AL40: =AK40+'Planning Model'!J49+'Planning Model'!J104-'Planning Model'!J164 -> 0 | AM40: =AL40+'Planning Model'!K49+'Planning Model'!K104-'Planning Model'!K164 -> 0 | AN40: =AM40+'Planning Model'!L49+'Planning Model'!L104-'Planning Model'!L164 -> 0 | ... AX40: =AW40+'Planning Model'!V49+'Planning Model'!V104-'Planning Model'!V164 -> 0
A41: HW | B41: HASS | C41: WTCT | D41: 171.66667 | E41: 0 | F41: 0 | G41: 0 | H41: 0 | I41: 0 | J41: 0 | K41: 0 | L41: 120.88738 | M41: 62.484326 | N41: 6.8482012 | O41: 40.68792 | P41: 32.550336 | Q41: 8.505 | R41: 0 | S41: 0 | T41: 0 | U41: 0 | V41: 0 | W41: =D41*SUM(E41:V41) -> 46687.01 | AB41: SW | AC41: CJER | AF41: 0 | AG41: =AF41+'Planning Model'!E26+'Planning Model'!E50+'Planning Model'!E81+'Planning Model'!E105-'Planning Model'!E165 -> 816.48 | AH41: =AG41+'Planning Model'!F26+'Planning Model'!F50+'Planning Model'!F81+'Planning Model'!F105-'Planning Model'!F165 -> 816.48 | AI41: =AH41+'Planning Model'!G26+'Planning Model'!G50+'Planning Model'!G81+'Planning Model'!G105-'Planning Model'!G165 -> 816.48 | AJ41: =AI41+'Planning Model'!H26+'Planning Model'!H50+'Planning Model'!H81+'Planning Model'!H105-'Planning Model'!H165 -> 790.965 | AK41: =AJ41+'Planning Model'!I26+'Planning Model'!I50+'Planning Model'!I81+'Planning Model'!I105-'Planning Model'!I165 -> 748.44 | AL41: =AK41+'Planning Model'!J26+'Planning Model'!J50+'Planning Model'!J81+'Planning Model'!J105-'Planning Model'!J165 -> 697.41 | AM41: =AL41+'Planning Model'!K26+'Planning Model'!K50+'Planning Model'!K81+'Planning Model'!K105-'Planning Model'!K165 -> 612.36 | AN41: =AM41+'Planning Model'!L26+'Planning Model'!L50+'Planning Model'!L81+'Planning Model'!L105-'Planning Model'!L165 -> 484.785 | ... AX41: =AW41+'Planning Model'!V26+'Planning Model'!V50+'Planning Model'!V81+'Planning Model'!V105-'Planning Model'!V165 -> 1.2079227e-13
A42: HW | B42: HASS | C42: WTMA | D42: 170 | E42: 0 | F42: 0 | G42: 0 | H42: 0 | I42: 0 | J42: 0 | K42: 0 | L42: 0 | M42: 0 | N42: 0 | O42: 0 | P42: 0 | Q42: 0 | R42: 0 | S42: 0 | T42: 0 | U42: 0 | V42: 0 | W42: =D42*SUM(E42:V42) -> 0 | AB42: SW | AC42: CTRI | AF42: 75 | AG42: =AF42+'Planning Model'!E51+'Planning Model'!E67+'Planning Model'!E106+'Planning Model'!E122-'Planning Model'!E166-'Planning Model'!E170-'Planning Model'!E179-'Planning Model'!E186 -> 5.9205 | AH42: =AG42+'Planning Model'!F51+'Planning Model'!F67+'Planning Model'!F106+'Planning Model'!F122-'Planning Model'!F166-'Planning Model'!F170-'Planning Model'!F179-'Planning Model'!F186 -> 0 | AI42: =AH42+'Planning Model'!G51+'Planning Model'!G67+'Planning Model'!G106+'Planning Model'!G122-'Planning Model'!G166-'Planning Model'!G170-'Planning Model'!G179-'Planning Model'!G186 -> 0 | AJ42: =AI42+'Planning Model'!H51+'Planning Model'!H67+'Planning Model'!H106+'Planning Model'!H122-'Planning Model'!H166-'Planning Model'!H170-'Planning Model'!H179-'Planning Model'!H186 -> 0 | AK42: =AJ42+'Planning Model'!I51+'Planning Model'!I67+'Planning Model'!I106+'Planning Model'!I122-'Planning Model'!I166-'Planning Model'!I170-'Planning Model'!I179-'Planning Model'!I186 -> 0 | AL42: =AK42+'Planning Model'!J51+'Planning Model'!J67+'Planning Model'!J106+'Planning Model'!J122-'Planning Model'!J166-'Planning Model'!J170-'Planning Model'!J179-'Planning Model'!J186 -> 0 | AM42: =AL42+'Planning Model'!K51+'Planning Model'!K67+'Planning Model'!K106+'Planning Model'!K122-'Planning Model'!K166-'Planning Model'!K170-'Planning Model'!K179-'Planning Model'!K186 -> 0 | AN42: =AM42+'Planning Model'!L51+'Planning Model'!L67+'Planning Model'!L106+'Planning Model'!L122-'Planning Model'!L166-'Planning Model'!L170-'Planning Model'!L179-'Planning Model'!L186 -> 0 | ... AX42: =AW42+'Planning Model'!V51+'Planning Model'!V67+'Planning Model'!V106+'Planning Model'!V122-'Planning Model'!V166-'Planning Model'!V170-'Planning Model'!V179-'Planning Model'!V186 -> 4e-05
A43: HW | B43: JAFF | C43: BERK | D43: 41.666667 | E43: 0 | F43: 0 | G43: 0 | H43: 0 | I43: 0 | J43: 0 | K43: 0 | L43: 0 | M43: 0 | N43: 0 | O43: 0 | P43: 0 | Q43: 0 | R43: 0 | S43: 0 | T43: 0 | U43: 0 | V43: 0 | W43: =D43*SUM(E43:V43) -> 0 | AB43: SW | AC43: DEME | AF43: 150 | AG43: =AF43+'Planning Model'!E30+'Planning Model'!E52+'Planning Model'!E68+'Planning Model'!E85+'Planning Model'!E107+'Planning Model'!E123-'Planning Model'!E167 -> 95.757 | AH43: =AG43+'Planning Model'!F30+'Planning Model'!F52+'Planning Model'!F68+'Planning Model'!F85+'Planning Model'!F107+'Planning Model'!F123-'Planning Model'!F167 -> 17.22372 | AI43: =AH43+'Planning Model'!G30+'Planning Model'!G52+'Planning Model'!G68+'Planning Model'!G85+'Planning Model'!G107+'Planning Model'!G123-'Planning Model'!G167 -> 147.65864 | AJ43: =AI43+'Planning Model'!H30+'Planning Model'!H52+'Planning Model'!H68+'Planning Model'!H85+'Planning Model'!H107+'Planning Model'!H123-'Planning Model'!H167 -> 183.08336 | AK43: =AJ43+'Planning Model'!I30+'Planning Model'!I52+'Planning Model'!I68+'Planning Model'!I85+'Planning Model'!I107+'Planning Model'!I123-'Planning Model'!I167 -> 130.5408 | AL43: =AK43+'Planning Model'!J30+'Planning Model'!J52+'Planning Model'!J68+'Planning Model'!J85+'Planning Model'!J107+'Planning Model'!J123-'Planning Model'!J167 -> 5.732974 | AM43: =AL43+'Planning Model'!K30+'Planning Model'!K52+'Planning Model'!K68+'Planning Model'!K85+'Planning Model'!K107+'Planning Model'!K123-'Planning Model'!K167 -> 4e-06 | AN43: =AM43+'Planning Model'!L30+'Planning Model'!L52+'Planning Model'!L68+'Planning Model'!L85+'Planning Model'!L107+'Planning Model'!L123-'Planning Model'!L167 -> 4e-06 | ... AX43: =AW43+'Planning Model'!V30+'Planning Model'!V52+'Planning Model'!V68+'Planning Model'!V85+'Planning Model'!V107+'Planning Model'!V123-'Planning Model'!V167 -> 2e-06
A44: HW | B44: JAFF | C44: SONH | D44: 33.333333 | E44: 105.825 | F44: 187.06014 | G44: 220 | H44: 115.49056 | I44: 130.1872 | J44: 126.74268 | K44: 39.273764 | L44: 0 | M44: 0 | N44: 0 | O44: 0 | P44: 0 | Q44: 301.68375 | R44: 440 | S44: 440 | T44: 440 | U44: 305.2808 | V44: 400.11401 | W44: =D44*SUM(E44:V44) -> 108388.6 | AB44: SW | AC44: HUDV | AF44: 500 | AG44: =AF44+'Planning Model'!E27+'Planning Model'!E53+'Planning Model'!E69+'Planning Model'!E82+'Planning Model'!E108+'Planning Model'!E124-'Planning Model'!E169 -> 292.46 | AH44: =AG44+'Planning Model'!F27+'Planning Model'!F53+'Planning Model'!F69+'Planning Model'!F82+'Planning Model'!F108+'Planning Model'!F124-'Planning Model'!F169 -> 853.73489 | AI44: =AH44+'Planning Model'!G27+'Planning Model'!G53+'Planning Model'!G69+'Planning Model'!G82+'Planning Model'!G108+'Planning Model'!G124-'Planning Model'!G169 -> 949.11315 | AJ44: =AI44+'Planning Model'!H27+'Planning Model'!H53+'Planning Model'!H69+'Planning Model'!H82+'Planning Model'!H108+'Planning Model'!H124-'Planning Model'!H169 -> 1096.9726 | AK44: =AJ44+'Planning Model'!I27+'Planning Model'!I53+'Planning Model'!I69+'Planning Model'!I82+'Planning Model'!I108+'Planning Model'!I124-'Planning Model'!I169 -> 842.45852 | AL44: =AK44+'Planning Model'!J27+'Planning Model'!J53+'Planning Model'!J69+'Planning Model'!J82+'Planning Model'!J108+'Planning Model'!J124-'Planning Model'!J169 -> 77.0138 | AM44: =AL44+'Planning Model'!K27+'Planning Model'!K53+'Planning Model'!K69+'Planning Model'!K82+'Planning Model'!K108+'Planning Model'!K124-'Planning Model'!K169 -> -1e-05 | AN44: =AM44+'Planning Model'!L27+'Planning Model'!L53+'Planning Model'!L69+'Planning Model'!L82+'Planning Model'!L108+'Planning Model'!L124-'Planning Model'!L169 -> -1e-05 | ... AX44: =AW44+'Planning Model'!V27+'Planning Model'!V53+'Planning Model'!V69+'Planning Model'!V82+'Planning Model'!V108+'Planning Model'!V124-'Planning Model'!V169 -> -4e-05
A45: HW | B45: JAFF | C45: UVLY | D45: 33.333333 | E45: 14.175 | F45: 32.939865 | G45: 0 | H45: 104.50944 | I45: 89.8128 | J45: 93.257325 | K45: 180.72624 | L45: 0 | M45: 0 | N45: 0 | O45: 0 | P45: 0 | Q45: 21.2625 | R45: 0 | S45: 0 | T45: 0 | U45: 134.7192 | V45: 39.885987 | W45: =D45*SUM(E45:V45) -> 23709.612 | AB45: SW | AC45: NCMA | AF45: 500 | AG45: =AF45+'Planning Model'!E31+'Planning Model'!E54+'Planning Model'!E70+'Planning Model'!E86+'Planning Model'!E109+'Planning Model'!E125-'Planning Model'!E173 -> 297.77 | AH45: =AG45+'Planning Model'!F31+'Planning Model'!F54+'Planning Model'!F70+'Planning Model'!F86+'Planning Model'!F109+'Planning Model'!F125-'Planning Model'!F173 -> 555.67795 | AI45: =AH45+'Planning Model'!G31+'Planning Model'!G54+'Planning Model'!G70+'Planning Model'!G86+'Planning Model'!G109+'Planning Model'!G125-'Planning Model'!G173 -> 991.94985 | AJ45: =AI45+'Planning Model'!H31+'Planning Model'!H54+'Planning Model'!H70+'Planning Model'!H86+'Planning Model'!H109+'Planning Model'!H125-'Planning Model'!H173 -> -4.4e-05 | AK45: =AJ45+'Planning Model'!I31+'Planning Model'!I54+'Planning Model'!I70+'Planning Model'!I86+'Planning Model'!I109+'Planning Model'!I125-'Planning Model'!I173 -> -4.4e-05 | AL45: =AK45+'Planning Model'!J31+'Planning Model'!J54+'Planning Model'!J70+'Planning Model'!J86+'Planning Model'!J109+'Planning Model'!J125-'Planning Model'!J173 -> -4.4e-05 | AM45: =AL45+'Planning Model'!K31+'Planning Model'!K54+'Planning Model'!K70+'Planning Model'!K86+'Planning Model'!K109+'Planning Model'!K125-'Planning Model'!K173 -> -4.4e-05 | AN45: =AM45+'Planning Model'!L31+'Planning Model'!L54+'Planning Model'!L70+'Planning Model'!L86+'Planning Model'!L109+'Planning Model'!L125-'Planning Model'!L173 -> -4.4e-05 | ... AX45: =AW45+'Planning Model'!V31+'Planning Model'!V54+'Planning Model'!V70+'Planning Model'!V86+'Planning Model'!V109+'Planning Model'!V125-'Planning Model'!V173 -> -3.4e-05
...

Sheet RegionalDemand
A1: This Sheet takes the forecast by region (rows 7 - 20) and converts it into a forecast by type of wood (HW, SW), and inflates it by 5%, according to the WPD planning policy
A2: The final demand forecast (rows 28 to 55) is the demand forecast used in the planning model (rows 286 to 313 on Planning Model sheet)
A4: Demand by Region in Tons, including % hardwood
A6: RegionID | B6: RegionName | C6: HW | D6: 44256 | E6: 44287 | F6: 44317 | G6: 44348 | H6: 44378 | I6: 44409 | J6: 44440 | K6: 44470 | L6: 44501 | M6: 44531 | N6: 44562 | O6: 44593 | P6: 44621 | Q6: 44652 | R6: 44682 | S6: 44713 | T6: 44743 | U6: 44774
A7: BERK | B7: Berkshire | C7: 0.25 | D7: 178.2 | E7: 263.7765 | F7: 383.454 | G7: 616.248 | H7: 537.03 | I7: 523.5435 | J7: 810.891 | K7: 812.349 | L7: 342.873 | M7: 183.951 | N7: 183.951 | O7: 147.1608 | P7: 267.3 | Q7: 395.66475 | R7: 575.181 | S7: 924.372 | T7: 805.545 | U7: 785.31525
A8: CJER | B8: Central NJ | C8: 0.1 | D8: 36 | E8: 36 | F8: 54 | G8: 27 | H8: 45 | I8: 54 | J8: 90 | K8: 135 | L8: 135 | M8: 108 | N8: 72 | O8: 72 | P8: 63 | Q8: 54 | R8: 36 | S8: 27 | T8: 18 | U8: 18
A9: CTRI | B9: East CT-RI | C9: 0.15 | D9: 77.4 | E9: 194.472 | F9: 281.376 | G9: 401.112 | H9: 614.736 | I9: 826.992 | J9: 684.504 | K9: 510.984 | L9: 246.672 | M9: 141.912 | N9: 141.912 | O9: 113.5296 | P9: 116.1 | Q9: 291.708 | R9: 422.064 | S9: 601.668 | T9: 922.104 | U9: 1240.488
A10: DEME | B10: Downeast ME | C10: 0.3 | D10: 73.8 | E10: 106.848 | F10: 298.728 | G10: 564.048 | H10: 298.368 | I10: 221.112 | J10: 209.736 | K10: 174.312 | L10: 79.236 | M10: 57.744 | N10: 57.744 | O10: 46.1952 | P10: 110.7 | Q10: 160.272 | R10: 448.092 | S10: 846.072 | T10: 447.552 | U10: 331.668
A11: HUDV | B11: Hudson Valley | C11: 0.15 | D11: 288 | E11: 491.56875 | F11: 605.57625 | G11: 938.79 | H11: 1179.8663 | I11: 1185.3337 | J11: 969.26625 | K11: 944.35875 | L11: 573.48 | M11: 323.69625 | N11: 323.69625 | O11: 258.957 | P11: 432 | Q11: 737.35312 | R11: 908.36437 | S11: 1408.185 | T11: 1769.7994 | U11: 1778.0006
A12: NCMA | B12: N-Central Mass | C12: 0.2 | D12: 240.75 | E12: 611.82 | F12: 843.75 | G12: 1208.97 | H12: 1727.55 | I12: 1898.73 | J12: 2063.79 | K12: 1567.17 | L12: 724.14 | M12: 369.36 | N12: 369.36 | O12: 295.488 | P12: 361.125 | Q12: 917.73 | R12: 1265.625 | S12: 1813.455 | T12: 2591.325 | U12: 2848.095
A13: NJER | B13: North NJ | C13: 0.1 | D13: 31.5 | E13: 77.22 | F13: 172.44 | G13: 171.09 | H13: 213.21 | I13: 255.6 | J13: 301.59 | K13: 393.21 | L13: 169.47 | M13: 113.49 | N13: 113.49 | O13: 90.792 | P13: 47.25 | Q13: 115.83 | R13: 258.66 | S13: 256.635 | T13: 319.815 | U13: 383.4
A14: OHIO | B14: Ohio | C14: 0.15 | D14: 30.6 | E14: 34.128 | F14: 26.892 | G14: 34.722 | H14: 49.302 | I14: 59.508 | J14: 51.516 | K14: 91.908 | L14: 86.4 | M14: 58.914 | N14: 58.914 | O14: 47.1312 | P14: 45.9 | Q14: 51.192 | R14: 40.338 | S14: 52.083 | T14: 73.953 | U14: 89.262
A15: SCST | B15: MA-ME Seacoast | C15: 0.2 | D15: 79.2 | E15: 519.21 | F15: 991.359 | G15: 1517.454 | H15: 1787.508 | I15: 1479.546 | J15: 1400.247 | K15: 1173.042 | L15: 535.086 | M15: 308.124 | N15: 308.124 | O15: 246.4992 | P15: 118.8 | Q15: 778.815 | R15: 1487.0385 | S15: 2276.181 | T15: 2681.262 | U15: 2219.319
A16: SEMA | B16: SE Mass-RI | C16: 0.15 | D16: 79.2 | E16: 258.111 | F16: 395.766 | G16: 499.905 | H16: 964.341 | I16: 1072.449 | J16: 1277.073 | K16: 769.419 | L16: 382.284 | M16: 265.734 | N16: 265.734 | O16: 212.5872 | P16: 118.8 | Q16: 387.1665 | R16: 593.649 | S16: 749.8575 | T16: 1446.5115 | U16: 1608.6735
A17: SONH | B17: NH South | C17: 0.3 | D17: 153 | E17: 374.22 | F17: 656.343 | G17: 1191.348 | H17: 1384.938 | I17: 1165.185 | J17: 1057.131 | K17: 992.007 | L17: 492.156 | M17: 810.405 | N17: 450 | O17: 360 | P17: 229.5 | Q17: 561.33 | R17: 984.5145 | S17: 1787.022 | T17: 2077.407 | U17: 1747.7775
A18: UVLY | B18: NH Upper Valley | C18: 0.3 | D18: 45 | E18: 104.571 | F18: 166.536 | G18: 331.776 | H18: 285.12 | I18: 296.055 | J18: 335.745 | K18: 203.148 | L18: 110.079 | M18: 86.508 | N18: 86.508 | O18: 69.2064 | P18: 67.5 | Q18: 156.8565 | R18: 249.804 | S18: 497.664 | T18: 427.68 | U18: 444.0825
... A20: WTMA | B20: West Mass | C20: 0.2 | D20: 51.75 | E20: 102.33 | F20: 119.5425 | G20: 189.945 | H20: 304.155 | I20: 367.6725 | J20: 389.0025 | K20: 287.4825 | L20: 180.1575 | M20: 118.5975 | N20: 118.5975 | O20: 94.878 | P20: 77.625 | Q20: 153.495 | R20: 179.31375 | S20: 284.9175 | T20: 456.2325 | U20: 551.50875
C22: Total | D22: =SUM(D7:D20) -> 1400.4 | E22: =SUM(E7:E20) -> 3505.4032 | F22: =SUM(F7:F20) -> 5483.7787 | G22: =SUM(G7:G20) -> 8309.088 | H22: =SUM(H7:H20) -> 10373.276 | I22: =SUM(I7:I20) -> 10552.903 | J22: =SUM(J7:J20) -> 10930.732 | K22: =SUM(K7:K20) -> 9009.9022 | ... U22: =SUM(U7:U20) -> 15766.354
C23: Hardwood | D23: =SUMPRODUCT($C7:$C18,D7:D18) -> 268.11 | E23: =SUMPRODUCT($C7:$C18,E7:E18) -> 625.90579 | F23: =SUMPRODUCT($C7:$C18,F7:F18) -> 1018.4529 | G23: =SUMPRODUCT($C7:$C18,G7:G18) -> 1626.4868 | H23: =SUMPRODUCT($C7:$C18,H7:H18) -> 1874.8547 | I23: =SUMPRODUCT($C7:$C18,I7:I18) -> 1813.8491 | J23: =SUMPRODUCT($C7:$C18,J7:J18) -> 1862.8266 | K23: =SUMPRODUCT($C7:$C18,K7:K18) -> 1562.2912 | ... U23: =SUMPRODUCT($C7:$C18,U7:U18) -> 2714.4736
A25: demand muliplier | C25: 1.05
A27: Product | B27: RegionID | C27: RegionName | D27: 44256 | E27: 44287 | F27: 44317 | G27: 44348 | H27: 44378 | I27: 44409 | J27: 44440 | K27: 44470 | L27: 44501 | M27: 44531 | N27: 44562 | O27: 44593 | P27: 44621 | Q27: 44652 | R27: 44682 | S27: 44713 | T27: 44743 | U27: 44774
A28: HW | B28: BERK | C28: Berkshire | D28: =$C$25*$C7*D7 -> 46.7775 | E28: =$C$25*$C7*E7 -> 69.241331 | F28: =$C$25*$C7*F7 -> 100.65668 | G28: =$C$25*$C7*G7 -> 161.7651 | H28: =$C$25*$C7*H7 -> 140.97037 | I28: =$C$25*$C7*I7 -> 137.43017 | J28: =$C$25*$C7*J7 -> 212.85889 | K28: =$C$25*$C7*K7 -> 213.24161 | ... U28: =$C$25*$C7*U7 -> 206.14525
A29: HW | B29: CJER | C29: Central NJ | D29: =$C$25*$C8*D8 -> 3.78 | E29: =$C$25*$C8*E8 -> 3.78 | F29: =$C$25*$C8*F8 -> 5.67 | G29: =$C$25*$C8*G8 -> 2.835 | H29: =$C$25*$C8*H8 -> 4.725 | I29: =$C$25*$C8*I8 -> 5.67 | J29: =$C$25*$C8*J8 -> 9.45 | K29: =$C$25*$C8*K8 -> 14.175 | ... U29: =$C$25*$C8*U8 -> 1.89
A30: HW | B30: CTRI | C30: East CT-RI | D30: =$C$25*$C9*D9 -> 12.1905 | E30: =$C$25*$C9*E9 -> 30.62934 | F30: =$C$25*$C9*F9 -> 44.31672 | G30: =$C$25*$C9*G9 -> 63.17514 | H30: =$C$25*$C9*H9 -> 96.82092 | I30: =$C$25*$C9*I9 -> 130.25124 | J30: =$C$25*$C9*J9 -> 107.80938 | K30: =$C$25*$C9*K9 -> 80.47998 | ... U30: =$C$25*$C9*U9 -> 195.37686
A31: HW | B31: DEME | C31: Downeast ME | D31: =$C$25*$C10*D10 -> 23.247 | E31: =$C$25*$C10*E10 -> 33.65712 | F31: =$C$25*$C10*F10 -> 94.09932 | G31: =$C$25*$C10*G10 -> 177.67512 | H31: =$C$25*$C10*H10 -> 93.98592 | I31: =$C$25*$C10*I10 -> 69.65028 | J31: =$C$25*$C10*J10 -> 66.06684 | K31: =$C$25*$C10*K10 -> 54.90828 | ... U31: =$C$25*$C10*U10 -> 104.47542
A32: HW | B32: HUDV | C32: Hudson Valley | D32: =$C$25*$C11*D11 -> 45.36 | E32: =$C$25*$C11*E11 -> 77.422078 | F32: =$C$25*$C11*F11 -> 95.378259 | G32: =$C$25*$C11*G11 -> 147.85942 | H32: =$C$25*$C11*H11 -> 185.82893 | I32: =$C$25*$C11*I11 -> 186.69007 | J32: =$C$25*$C11*J11 -> 152.65943 | K32: =$C$25*$C11*K11 -> 148.7365 | ... U32: =$C$25*$C11*U11 -> 280.0351
A33: HW | B33: NCMA | C33: N-Central Mass | D33: =$C$25*$C12*D12 -> 50.5575 | E33: =$C$25*$C12*E12 -> 128.4822 | F33: =$C$25*$C12*F12 -> 177.1875 | G33: =$C$25*$C12*G12 -> 253.8837 | H33: =$C$25*$C12*H12 -> 362.7855 | I33: =$C$25*$C12*I12 -> 398.7333 | J33: =$C$25*$C12*J12 -> 433.3959 | K33: =$C$25*$C12*K12 -> 329.1057 | ... U33: =$C$25*$C12*U12 -> 598.09995
A34: HW | B34: NJER | C34: North NJ | D34: =$C$25*$C13*D13 -> 3.3075 | E34: =$C$25*$C13*E13 -> 8.1081 | F34: =$C$25*$C13*F13 -> 18.1062 | G34: =$C$25*$C13*G13 -> 17.96445 | H34: =$C$25*$C13*H13 -> 22.38705 | I34: =$C$25*$C13*I13 -> 26.838 | J34: =$C$25*$C13*J13 -> 31.66695 | K34: =$C$25*$C13*K13 -> 41.28705 | ... U34: =$C$25*$C13*U13 -> 40.257
A35: HW | B35: OHIO | C35: Ohio | D35: =$C$25*$C14*D14 -> 4.8195 | E35: =$C$25*$C14*E14 -> 5.37516 | F35: =$C$25*$C14*F14 -> 4.23549 | G35: =$C$25*$C14*G14 -> 5.468715 | H35: =$C$25*$C14*H14 -> 7.765065 | I35: =$C$25*$C14*I14 -> 9.37251 | J35: =$C$25*$C14*J14 -> 8.11377 | K35: =$C$25*$C14*K14 -> 14.47551 | ... U35: =$C$25*$C14*U14 -> 14.058765
A36: HW | B36: SCST | C36: MA-ME Seacoast | D36: =$C$25*$C15*D15 -> 16.632 | E36: =$C$25*$C15*E15 -> 109.0341 | F36: =$C$25*$C15*F15 -> 208.18539 | G36: =$C$25*$C15*G15 -> 318.66534 | H36: =$C$25*$C15*H15 -> 375.37668 | I36: =$C$25*$C15*I15 -> 310.70466 | J36: =$C$25*$C15*J15 -> 294.05187 | K36: =$C$25*$C15*K15 -> 246.33882 | ... U36: =$C$25*$C15*U15 -> 466.05699
A37: HW | B37: SEMA | C37: SE Mass-RI | D37: =$C$25*$C16*D16 -> 12.474 | E37: =$C$25*$C16*E16 -> 40.652482 | F37: =$C$25*$C16*F16 -> 62.333145 | G37: =$C$25*$C16*G16 -> 78.735038 | H37: =$C$25*$C16*H16 -> 151.88371 | I37: =$C$25*$C16*I16 -> 168.91072 | J37: =$C$25*$C16*J16 -> 201.139 | K37: =$C$25*$C16*K16 -> 121.18349 | ... U37: =$C$25*$C16*U16 -> 253.36608
A38: HW | B38: SONH | C38: NH South | D38: =$C$25*$C17*D17 -> 48.195 | E38: =$C$25*$C17*E17 -> 117.8793 | F38: =$C$25*$C17*F17 -> 206.74804 | G38: =$C$25*$C17*G17 -> 375.27462 | H38: =$C$25*$C17*H17 -> 436.25547 | I38: =$C$25*$C17*I17 -> 367.03327 | J38: =$C$25*$C17*J17 -> 332.99626 | K38: =$C$25*$C17*K17 -> 312.4822 | ... U38: =$C$25*$C17*U17 -> 550.54991
A39: HW | B39: UVLY | C39: NH Upper Valley | D39: =$C$25*$C18*D18 -> 14.175 | E39: =$C$25*$C18*E18 -> 32.939865 | F39: =$C$25*$C18*F18 -> 52.45884 | G39: =$C$25*$C18*G18 -> 104.50944 | H39: =$C$25*$C18*H18 -> 89.8128 | I39: =$C$25*$C18*I18 -> 93.257325 | J39: =$C$25*$C18*J18 -> 105.75968 | K39: =$C$25*$C18*K18 -> 63.99162 | ... U39: =$C$25*$C18*U18 -> 139.88599
... A41: HW | B41: WTMA | C41: West Mass | D41: =$C$25*$C20*D20 -> 10.8675 | E41: =$C$25*$C20*E20 -> 21.4893 | F41: =$C$25*$C20*F20 -> 25.103925 | G41: =$C$25*$C20*G20 -> 39.88845 | H41: =$C$25*$C20*H20 -> 63.87255 | I41: =$C$25*$C20*I20 -> 77.211225 | J41: =$C$25*$C20*J20 -> 81.690525 | K41: =$C$25*$C20*K20 -> 60.371325 | ... U41: =$C$25*$C20*U20 -> 115.81684
A42: SW | B42: BERK | C42: Berkshire | D42: =$C$25*(1-$C7)*D7 -> 140.3325 | E42: =$C$25*(1-$C7)*E7 -> 207.72399 | F42: =$C$25*(1-$C7)*F7 -> 301.97003 | G42: =$C$25*(1-$C7)*G7 -> 485.2953 | H42: =$C$25*(1-$C7)*H7 -> 422.91113 | I42: =$C$25*(1-$C7)*I7 -> 412.29051 | J42: =$C$25*(1-$C7)*J7 -> 638.57666 | K42: =$C$25*(1-$C7)*K7 -> 639.72484 | ... U42: =$C$25*(1-$C7)*U7 -> 618.43576
A43: SW | B43: CJER | C43: Central NJ | D43: =$C$25*(1-$C8)*D8 -> 34.02 | E43: =$C$25*(1-$C8)*E8 -> 34.02 | F43: =$C$25*(1-$C8)*F8 -> 51.03 | G43: =$C$25*(1-$C8)*G8 -> 25.515 | H43: =$C$25*(1-$C8)*H8 -> 42.525 | I43: =$C$25*(1-$C8)*I8 -> 51.03 | J43: =$C$25*(1-$C8)*J8 -> 85.05 | K43: =$C$25*(1-$C8)*K8 -> 127.575 | ... U43: =$C$25*(1-$C8)*U8 -> 17.01
A44: SW | B44: CTRI | C44: East CT-RI | D44: =$C$25*(1-$C9)*D9 -> 69.0795 | E44: =$C$25*(1-$C9)*E9 -> 173.56626 | F44: =$C$25*(1-$C9)*F9 -> 251.12808 | G44: =$C$25*(1-$C9)*G9 -> 357.99246 | H44: =$C$25*(1-$C9)*H9 -> 548.65188 | I44: =$C$25*(1-$C9)*I9 -> 738.09036 | J44: =$C$25*(1-$C9)*J9 -> 610.91982 | K44: =$C$25*(1-$C9)*K9 -> 456.05322 | ... U44: =$C$25*(1-$C9)*U9 -> 1107.1355
A45: SW | B45: DEME | C45: Downeast ME | D45: =$C$25*(1-$C10)*D10 -> 54.243 | E45: =$C$25*(1-$C10)*E10 -> 78.53328 | F45: =$C$25*(1-$C10)*F10 -> 219.56508 | G45: =$C$25*(1-$C10)*G10 -> 414.57528 | H45: =$C$25*(1-$C10)*H10 -> 219.30048 | I45: =$C$25*(1-$C10)*I10 -> 162.51732 | J45: =$C$25*(1-$C10)*J10 -> 154.15596 | K45: =$C$25*(1-$C10)*K10 -> 128.11932 | ... U45: =$C$25*(1-$C10)*U10 -> 243.77598
A46: SW | B46: HUDV | C46: Hudson Valley | D46: =$C$25*(1-$C11)*D11 -> 257.04 | E46: =$C$25*(1-$C11)*E11 -> 438.72511 | F46: =$C$25*(1-$C11)*F11 -> 540.4768 | G46: =$C$25*(1-$C11)*G11 -> 837.87007 | H46: =$C$25*(1-$C11)*H11 -> 1053.0306 | I46: =$C$25*(1-$C11)*I11 -> 1057.9104 | J46: =$C$25*(1-$C11)*J11 -> 865.07013 | K46: =$C$25*(1-$C11)*K11 -> 842.84018 | ... U46: =$C$25*(1-$C11)*U11 -> 1586.8656
A47: SW | B47: NCMA | C47: N-Central Mass | D47: =$C$25*(1-$C12)*D12 -> 202.23 | E47: =$C$25*(1-$C12)*E12 -> 513.9288 | F47: =$C$25*(1-$C12)*F12 -> 708.75 | G47: =$C$25*(1-$C12)*G12 -> 1015.5348 | H47: =$C$25*(1-$C12)*H12 -> 1451.142 | I47: =$C$25*(1-$C12)*I12 -> 1594.9332 | J47: =$C$25*(1-$C12)*J12 -> 1733.5836 | K47: =$C$25*(1-$C12)*K12 -> 1316.4228 | ... U47: =$C$25*(1-$C12)*U12 -> 2392.3998
...
